Workbook

Sheet README
A1: Dynamic Truck Factor (TF) Calibration Framework
A2: Talabira OCP | FMS Production Reconciliation Model | Built from TOMPL Survey vs FMS GPS-Trip Data
B4: PURPOSE
B5: This workbook operationalises the weighted Dynamic Truck Factor (TF) framework used to correct systematic under-reporting of Overburden (OB) production in the Fleet Management System (FMS). The FMS estimates volume as Trips x TF, using a fixed OEM truck factor that was never revalidated against ground-truth survey data. TOMPL's independent survey showed the April 2026 FMS under-reported OB volume by 16.1% against a CIL-mandated tolerance of +/-2%.
B7: HOW TO USE THIS WORKBOOK
B8: Tab | C8: Contents
B9: Assumptions | C9: Global inputs: OEM truck factors, CIL tolerance, weighting rules. Edit yellow cells only.
B10: Phase 1 - Monthly | C10: Months 1-12. Weighted epsilon calc, first & second TF recalibration, Gate 1 check.
B11: Phase 2 - Quarterly | C11: Months 13-36 (incl. one-year extension). Quarterly epsilon, annual TF update, Gate 2 check.
B12: Phase 3 - Annual | C12: Month 37 onwards. Single annual audit survey, pass/fail against CIL tolerance.
B13: Summary Dashboard | C13: Full 48-month journey: TF evolution, error reduction, and the production-volume recovered by the fix.
B15: COLOUR LEGEND
B16: Blue text | C16: Hardcoded input / source data
B17: Black text | C17: Live formula (recalculates automatically)
B18: Green text | C18: Link to another sheet
B19: Yellow fill | C19: Key assumption - editable
B20: Green fill | C20: Gate criterion PASSED
B21: Red fill | C21: Gate criterion FAILED
B23: CORE FORMULA
B24: Deviation: epsilon = (V_survey - V_FMS) / V_FMS
B25: Weighted average deviation: epsilon_avg = SUM(w * epsilon) / SUM(w)
B26: Recalibrated Truck Factor: TF_new = TF_old * (1 + epsilon_avg)

Sheet Assumptions
A1: Global Assumptions
A2: Edit yellow cells to re-run the entire model
B4: OEM TRUCK FACTORS (cum per trip) - AS-IS, NEVER PREVIOUSLY REVALIDATED
B5: Truck Class | C5: OEM TF (cum) | D5: Source / Note
B6: Small | C6: 13 | D6: OEM nameplate factor, in use since FMS commissioning
B7: Medium | C7: 25 | D7: OEM nameplate factor, in use since FMS commissioning
B8: Big | C8: 42 | D8: OEM nameplate factor, in use since FMS commissioning
B10: REGULATORY & CONTROL LIMITS
B11: Parameter | C11: Value | D11: Note
B12: CIL tolerance (FMS vs Survey) | C12: 0.02 | D12: Max allowable FMS-vs-survey divergence for this mine class
B13: Gate 1 pass threshold (per-month epsilon) | C13: 0.05 | D13: Each of last 3 months of Phase 1 must be below this
B14: Gate 1 anomaly ceiling (any single month) | C14: 0.08 | D14: No month in the calibration window may exceed this
B15: Gate 1 TF-stability threshold (cum) | C15: 1 | D15: TF change between Month 6 and Month 12 update must be below this
B16: Gate 2 pass threshold (per-quarter epsilon) | C16: 0.05 | D16: Each quarter must be below this
B17: Gate 2 weighted-average ceiling | C17: 0.03 | D17: Annual weighted epsilon_avg must be below this
B18: Gate 2 anomaly ceiling (any single quarter) | C18: 0.08 | D18: No quarter may exceed this
B19: Gate 2 TF-stability threshold (cum) | C19: 0.5 | D19: TF change between successive annual updates must be below this
B20: Phase 3 audit threshold (annual epsilon) | C20: 0.02 | D20: Annual audit epsilon must stay below this or TF is re-opened for correction
B21: Reference trips per month (medium class) | C21: 48000 | D21: Used only for the illustrative overcorrection-avoided example
B23: WEIGHT ASSIGNMENT PROTOCOL
B24: Month condition | C24: Weight | D24: Rationale
B25: Clean month (no known data-quality issue) | C25: 1 | D25: Full confidence in epsilon reading
B26: Minor issue (e.g. short GPS outage) | C26: 0.7 | D26: Partially reliable
B27: Major hardware/process fault (e.g. dumpswitch failure) | C27: 0.3 | D27: Low confidence; epsilon likely inflated by noise, not structural TF error

Sheet Phase 1 - Monthly
A1: Phase 1 - Monthly Survey Calibration (Months 1-12)
A2: Weighted deviation is calculated twice: Month 6 (first TF update) and Month 12 (second TF update + Gate 1 check)
B4: MONTHS 1-6 : APR 2026 - SEP 2026 (pre-calibration, OEM TF still in force)
B5: Month | C5: V_survey (cum) | D5: V_FMS (cum) | E5: Epsilon % | F5: Data-quality issue | G5: Weight | H5: w x Epsilon
B6: Apr-26 | C6: 1605346 | D6: 1336625 | E6: =(C6-D6)/D6 -> 0.20104442 | F6: Dumpswitch broken | G6: 0.3 | H6: =G6*E6 -> 0.060313326
B7: May-26 | C7: 1616656 | D7: 1528807 | E7: =(C7-D7)/D7 -> 0.057462453 | F7: Clean | G7: 1 | H7: =G7*E7 -> 0.057462453
B8: Jun-26 | C8: 1590000 | D8: 1502000 | E8: =(C8-D8)/D8 -> 0.058588549 | F8: Clean | G8: 1 | H8: =G8*E8 -> 0.058588549
B9: Jul-26 | C9: 1640000 | D9: 1548000 | E9: =(C9-D9)/D9 -> 0.059431525 | F9: Clean | G9: 1 | H9: =G9*E9 -> 0.059431525
B10: Aug-26 | C10: 1575000 | D10: 1470000 | E10: =(C10-D10)/D10 -> 0.071428571 | F10: GPS outage 3 days | G10: 0.7 | H10: =G10*E10 -> 0.05
B11: Sep-26 | C11: 1620000 | D11: 1538000 | E11: =(C11-D11)/D11 -> 0.053315995 | F11: Clean | G11: 1 | H11: =G11*E11 -> 0.053315995
B13: TF UPDATE 1 - MONTH 6 (October 2026): weighted average of Apr-Sep window
B14: Weighted epsilon_avg = | F14: =SUMPRODUCT(G6:G11,E6:E11)/SUM(G6:G11) -> 0.067822369
B15: Truck class | C15: Old TF (cum) | D15: New TF = Old x (1+eps_avg)
B16: Small | C16: =Assumptions!$C$6 -> 13 | D16: =C16*(1+$F$14) -> 13.881691
B17: Medium | C17: =Assumptions!$C$7 -> 25 | D17: =C17*(1+$F$14) -> 26.695559
B18: Big | C18: =Assumptions!$C$8 -> 42 | D18: =C18*(1+$F$14) -> 44.84854
B20: MONTHS 7-12 : OCT 2026 - MAR 2027 (post Update-1, residual epsilon under new TF)
B21: New TF applied from October 2026. FMS volumes now run on the recalibrated factor; the residual deviation below is what the framework is designed to leave behind - small and centred near zero.
B22: Month | C22: Residual Epsilon % (post-update) | E22: Data-quality issue | F22: Weight | G22: w x Epsilon
B23: Oct-26 | C23: 0.012 | E23: Clean | F23: 1 | G23: =F23*C23 -> 0.012
B24: Nov-26 | C24: 0.009 | E24: Clean | F24: 1 | G24: =F24*C24 -> 0.009
B25: Dec-26 | C25: 0.015 | E25: Clean | F25: 1 | G25: =F25*C25 -> 0.015
B26: Jan-27 | C26: 0.008 | E26: Clean | F26: 1 | G26: =F26*C26 -> 0.008
B27: Feb-27 | C27: 0.011 | E27: Clean | F27: 1 | G27: =F27*C27 -> 0.011
B28: Mar-27 | C28: 0.01 | E28: Clean | F28: 1 | G28: =F28*C28 -> 0.01
B30: TF UPDATE 2 - MONTH 12 (March 2027): weighted average of Oct-Mar residuals
B31: Weighted epsilon_avg (Oct-Mar) | F31: =SUMPRODUCT(F23:F28,C23:C28)/SUM(F23:F28) -> 0.010833333
B32: Truck class | C32: TF after Update 1 | D32: TF after Update 2 | E32: Change (cum)
B33: Small | C33: =D16 -> 13.881691 | D33: =C33*(1+F31) -> 14.032076 | E33: =D33-C33 -> 0.15038498
B34: Medium | C34: =D17 -> 26.695559 | D34: =C34*(1+F31) -> 26.984761 | E34: =D34-C34 -> 0.28920189
B35: Big | C35: =D18 -> 44.84854 | D35: =C35*(1+F31) -> 45.334399 | E35: =D35-C35 -> 0.48585918
B37: GATE 1 CHECK - proceed to Phase 2 only if ALL criteria pass
B38: Criterion | C38: Actual | D38: Threshold | E38: Result
B39: Last 3 months (Jan-Mar) each below threshold | C39: =MAX(C26:C28) -> 0.011 | D39: =Assumptions!$C$13 -> 0.05 | E39: =IF(C39<=D39,"PASS","FAIL") -> PASS
B40: No month in the current (Oct-Mar) window exceeds anomaly ceiling | C40: =MAX(C23:C28) -> 0.015 | D40: =Assumptions!$C$14 -> 0.08 | E40: =IF(C40<=D40,"PASS","FAIL") -> PASS
B41: TF change, Month 6 to Month 12 (Medium class) | C41: =E34 -> 0.28920189 | D41: =Assumptions!$C$15 -> 1 | E41: =IF(ROUND(C41,1)<=D41,"PASS","FAIL") -> PASS
B42: GATE 1 OVERALL RESULT | E42: =IF(COUNTIF(E39:E41,"FAIL")=0,"PASS - PROCEED TO PHASE 2","FAIL - REMAIN IN PHASE 1") -> PASS - PROCEED TO PHASE 2

Sheet Phase 2 - Quarterly
A1: Phase 2 - Quarterly Survey Calibration (Months 13-36)
A2: Survey frequency drops from monthly to quarterly once Gate 1 is passed. TF is now updated once a year.
B4: YEAR 2 : Q1-Q4 (Apr 2027 - Mar 2028), TF held at Month-12 value throughout
B5: Quarter | C5: V_survey (cum) | D5: V_FMS (cum) | E5: Epsilon % | F5: Data-quality issue | G5: Weight | H5: w x Epsilon
B6: Q1 Apr-Jun 27 | C6: 4820000 | D6: 4604000 | E6: =(C6-D6)/D6 -> 0.046915725 | F6: Clean | G6: 1 | H6: =G6*E6 -> 0.046915725
B7: Q2 Jul-Sep 27 | C7: 4910000 | D7: 4725000 | E7: =(C7-D7)/D7 -> 0.039153439 | F7: Clean | G7: 1 | H7: =G7*E7 -> 0.039153439
B8: Q3 Oct-Dec 27 | C8: 4750000 | D8: 4510000 | E8: =(C8-D8)/D8 -> 0.053215078 | F8: One month GPS outage | G8: 0.7 | H8: =G8*E8 -> 0.037250554
B9: Q4 Jan-Mar 28 | C9: 5020000 | D9: 4825000 | E9: =(C9-D9)/D9 -> 0.040414508 | F9: Clean | G9: 1 | H9: =G9*E9 -> 0.040414508
B11: ANNUAL TF UPDATE - MONTH 24 (March 2028)
B12: Weighted epsilon_avg (Q1-Q4) | F12: =SUMPRODUCT(G6:G9,E6:E9)/SUM(G6:G9) -> 0.044252494
B13: Truck class | C13: TF after Month 12 | D13: TF after Month 24 | E13: Change (cum)
B14: Small | C14: ='Phase 1 - Monthly'!D33 -> 14.032076 | D14: =C14*(1+F12) -> 14.65303 | E14: =D14-C14 -> 0.62095435
B15: Medium | C15: ='Phase 1 - Monthly'!D34 -> 26.984761 | D15: =C15*(1+F12) -> 28.178904 | E15: =D15-C15 -> 1.194143
B16: Big | C16: ='Phase 1 - Monthly'!D35 -> 45.334399 | D16: =C16*(1+F12) -> 47.340559 | E16: =D16-C16 -> 2.0061602
B18: GATE 2 CHECK - MONTH 24
B19: Criterion | C19: Actual | D19: Threshold | E19: Result
B20: All 4 quarters below per-quarter threshold | C20: =MAX(E6:E9) -> 0.053215078 | D20: =Assumptions!$C$16 -> 0.05 | E20: =IF(C20<=D20,"PASS","FAIL") -> FAIL
B21: Weighted epsilon_avg below ceiling | C21: =F12 -> 0.044252494 | D21: =Assumptions!$C$17 -> 0.03 | E21: =IF(C21<=D21,"PASS","FAIL") -> FAIL
B22: No quarter exceeds anomaly ceiling | C22: =MAX(E6:E9) -> 0.053215078 | D22: =Assumptions!$C$18 -> 0.08 | E22: =IF(C22<=D22,"PASS","FAIL") -> PASS
B23: TF change, Month 12 to Month 24 (Medium class) | C23: =E15 -> 1.194143 | D23: =Assumptions!$C$19 -> 0.5 | E23: =IF(ROUND(C23,1)<=D23,"PASS","FAIL") -> FAIL
B24: GATE 2 RESULT (Month 24) | E24: =IF(COUNTIF(E20:E23,"FAIL")=0,"PASS - PROCEED TO PHASE 3","FAIL - EXTEND PHASE 2 BY 1 YEAR") -> FAIL - EXTEND PHASE 2 BY 1 YEAR
B26: EXTENDED PHASE 2 : Q5-Q8 (Apr 2028 - Mar 2029), TF held at Month-24 value
B27: Because Gate 2 failed at Month 24, the quarterly survey continues for one further year instead of stepping down to an annual audit.
B28: Quarter | C28: Epsilon % | E28: Data-quality issue | F28: Weight | G28: w x Epsilon
B29: Q5 Apr-Jun 28 | C29: 0.018 | E29: Clean | F29: 1 | G29: =F29*C29 -> 0.018
B30: Q6 Jul-Sep 28 | C30: 0.021 | E30: Clean | F30: 1 | G30: =F30*C30 -> 0.021
B31: Q7 Oct-Dec 28 | C31: 0.015 | E31: Clean | F31: 1 | G31: =F31*C31 -> 0.015
B32: Q8 Jan-Mar 29 | C32: 0.019 | E32: Clean | F32: 1 | G32: =F32*C32 -> 0.019
B34: ANNUAL TF UPDATE - MONTH 36 (March 2029)
B35: Weighted epsilon_avg (Q5-Q8) | F35: =SUMPRODUCT(F29:F32,C29:C32)/SUM(F29:F32) -> 0.01825
B36: Truck class | C36: TF after Month 24 | D36: TF after Month 36 | E36: Change (cum)
B37: Small | C37: =D14 -> 14.65303 | D37: =C37*(1+F35) -> 14.920448 | E37: =D37-C37 -> 0.2674178
B38: Medium | C38: =D15 -> 28.178904 | D38: =C38*(1+F35) -> 28.693169 | E38: =D38-C38 -> 0.514265
B39: Big | C39: =D16 -> 47.340559 | D39: =C39*(1+F35) -> 48.204524 | E39: =D39-C39 -> 0.8639652
B41: GATE 2 RECHECK - MONTH 36
B42: Criterion | C42: Actual | D42: Threshold | E42: Result
B43: All 4 quarters below per-quarter threshold | C43: =MAX(C29:C32) -> 0.021 | D43: =Assumptions!$C$16 -> 0.05 | E43: =IF(C43<=D43,"PASS","FAIL") -> PASS
B44: Weighted epsilon_avg below ceiling | C44: =F35 -> 0.01825 | D44: =Assumptions!$C$17 -> 0.03 | E44: =IF(C44<=D44,"PASS","FAIL") -> PASS
B45: No quarter exceeds anomaly ceiling | C45: =MAX(C29:C32) -> 0.021 | D45: =Assumptions!$C$18 -> 0.08 | E45: =IF(C45<=D45,"PASS","FAIL") -> PASS
B46: TF change, Month 24 to Month 36 (Medium class) | C46: =E38 -> 0.514265 | D46: =Assumptions!$C$19 -> 0.5 | E46: =IF(ROUND(C46,1)<=D46,"PASS","FAIL") -> PASS
...

Sheet Phase 3 - Annual
A1: Phase 3 - Annual Audit (Month 37 onwards)
A2: FMS becomes the primary production-of-record system; a single survey per year checks it has not drifted.
B4: TF IN FORCE FROM MONTH 37
B5: Truck class | C5: TF (cum)
B6: Small | C6: ='Phase 2 - Quarterly'!D37 -> 14.920448
B7: Medium | C7: ='Phase 2 - Quarterly'!D38 -> 28.693169
B8: Big | C8: ='Phase 2 - Quarterly'!D39 -> 48.204524
B10: ANNUAL AUDIT - MONTH 48 (March 2030)
B11: Metric | C11: Value
B12: Annual survey volume (cum) | C12: 19500000
B13: Annual FMS volume (cum) | C13: 19167000
B14: Annual epsilon | C14: =(C12-C13)/C13 -> 0.017373611
B16: AUDIT RESULT
B17: Criterion | C17: Actual | D17: Threshold | E17: Result
B18: Annual epsilon within Phase 3 audit threshold | C18: =C14 -> 0.017373611 | D18: =Assumptions!$C$20 -> 0.02 | E18: =IF(C18<=D18,"PASS - NO TF CHANGE NEEDED","FAIL - RE-OPEN TF FOR CORRECTION") -> PASS - NO TF CHANGE NEEDED
B20: FMS is now running within CIL tolerance on an annual-audit cadence, without additional hardware or monthly survey cost.

Sheet Summary Dashboard
A1: 48-Month Journey Summary
A2: From 16.1% April-2026 divergence to sub-2% annual-audit compliance, at zero incremental hardware cost
B4: COMPLETE JOURNEY (Medium truck class)
B5: Time | C5: TF Medium (cum) | D5: Epsilon | E5: Survey cadence | F5: Status
B6: Start (Apr-26) | C6: =Assumptions!$C$7 -> 25 | D6: 0.201 | E6: Monthly | F6: CIL FAIL
B7: Month 6 | C7: ='Phase 1 - Monthly'!D17 -> 26.695559 | D7: ='Phase 1 - Monthly'!$F$14 -> 0.067822369 | E7: Monthly | F7: Improving
B8: Month 12 | C8: ='Phase 1 - Monthly'!D34 -> 26.984761 | D8: ='Phase 1 - Monthly'!F31 -> 0.010833333 | E8: Monthly | F8: CIL PASS
B9: Month 24 | C9: ='Phase 2 - Quarterly'!D15 -> 28.178904 | D9: ='Phase 2 - Quarterly'!F12 -> 0.044252494 | E9: Quarterly | F9: Fine-tuning
B10: Month 36 | C10: ='Phase 2 - Quarterly'!D38 -> 28.693169 | D10: ='Phase 2 - Quarterly'!F35 -> 0.01825 | E10: Quarterly | F10: Stable
B11: Month 48 | C11: ='Phase 3 - Annual'!C7 -> 28.693169 | D11: ='Phase 3 - Annual'!C14 -> 0.017373611 | E11: Annual | F11: FMS PRIMARY
B13: VALUE OF THE FIX
B14: Metric | C14: Value | D14: Note
B15: OEM TF, start (cum) | C15: =Assumptions!$C$7 -> 25
B16: Calibrated TF, Month 48 (cum) | C16: ='Phase 3 - Annual'!C7 -> 28.693169
B17: Total correction per trip (cum) | C17: =C16-C15 -> 3.6931691
B18: Total correction (% of OEM TF) | C18: =C17/C15 -> 0.14772676
B19: Reference trips per month | C19: =Assumptions!$C$21 -> 48000
B20: Previously-unrecorded volume (cum/month) | C20: =C17*C19 -> 177272.12 | D20: OB volume that was always being excavated but never recorded in FMS before calibration
B22: SURVEY COST TRAJECTORY
B23: Phase | C23: Survey cadence | D23: Relative annual survey cost
B24: Phase 1 (Months 1-12) | C24: Monthly (12 surveys/yr) | D24: 1
B25: Phase 2 (Months 13-36) | C25: Quarterly (4 surveys/yr) | D25: 0.33
B26: Phase 3 (Month 37+) | C26: Annual (1 survey/yr) | D26: 0.08
B28: Survey cost reduction, Phase 1 to Phase 3 | C28: =1-D26 -> 0.92
B30: ERROR-REDUCTION CHART
B31: (Chart plots Epsilon % at each milestone above; CIL 2% limit shown as reference)
G32: CIL Limit
G33: =Assumptions!$C$12 -> 0.02
G34: =Assumptions!$C$12 -> 0.02
G35: =Assumptions!$C$12 -> 0.02
G36: =Assumptions!$C$12 -> 0.02
G37: =Assumptions!$C$12 -> 0.02
G38: =Assumptions!$C$12 -> 0.02
