Workbook

Sheet Raw Data
A1: RAW FMS DATA – APRIL 2025 | TALABIRA MINE | Adani Natural Resources
A2: Sr No | B2: Equipment Type | C2: Equipment ID | D2: Shift Hours | E2: Availabilty Hours | F2: Equipment Operation Hours | G2: Equipment Operation HMR | H2: Equipment Break Down Hours | I2: Equipment Break Down HMR | J2: Equipment Idle Hours | K2: Equipment Idle HMR | L2: Total Productive HMR | M2: Total Un-Productive HMR | N2: Total HMR | O2: Availibity % | P2: Utilization % | Q2: ROM Trip (Production) | R2: ROM Tones (Production) | S2: ROM Avg. | T2: OB Trip (Production) | U2: OB CUM (Production) | V2: TF | W2: Diesel Consumption | X2: Per Hour | Y2: Per Productive Hour (System With Load) | Z2: Per Productive Hour (System Without Load) | AA2: Per Trip | AB2: Per Ton/m3 | AC2: Equip Group | AD2: Status | AE2: Row Type
A3: 1 | B3: Tipper | C3: V-235 | D3: 720 | E3: 0.0597 | F3: 0.0597 | G3: 0.0597 | H3: 719.9403 | I3: 0 | J3: 0 | K3: 51.5781 | L3: 0.0597 | M3: 51.5781 | N3: 51.6378 | O3: 8.29167e-05 | P3: 1 | Q3: 0 | R3: 0 | S3: 0 | T3: 0 | U3: =T3*V3 -> 0 | V3: 13 | W3: 0 | X3: 0 | Y3: 0 | Z3: 0 | AA3: 0 | AB3: 0 | AC3: =IF(OR(TRIM(B3)="Tipper",TRIM(B3)="Volvo",TRIM(B3)="Bharatbenz"),"Tipper",IF(OR(TRIM(B3)="Dumper",TRIM(B3)="Sany",TRIM(B3)="Komatsu"),"Dumper",IF(TRIM(B3)="Excavator","Excavator",IF(OR(TRIM(B3)="Front End Loader",TRIM(B3)="Fel"),"Front End Loader",IF(OR(TRIM(B3)="Surface Miner",TRIM(B3)="Csm"),"Surface Miner",IF(TRIM(B3)="Diesel Bowser","Diesel Bowser","Other")))))) -> Tipper | AD3: =IF(E3=0,"Non-Operational","Operational") -> Operational | AE3: =IF(OR(C3=54,C3=67,C3=10,C3=16,C3=6,C3=12,C3=28),"Aggregate","Individual") -> Individual
A4: 2 | B4: Tipper | C4: V-236 | D4: 720 | E4: 0 | F4: 0 | G4: 0 | H4: 720 | I4: 0 | J4: 0 | K4: 0 | L4: 0 | M4: 0 | N4: 0 | O4: 0 | P4: 0 | Q4: 0 | R4: 0 | S4: 0 | T4: 0 | U4: =T4*V4 -> 0 | V4: 13 | W4: 0 | X4: 0 | Y4: 0 | Z4: 0 | AA4: 0 | AB4: 0 | AC4: =IF(OR(TRIM(B4)="Tipper",TRIM(B4)="Volvo",TRIM(B4)="Bharatbenz"),"Tipper",IF(OR(TRIM(B4)="Dumper",TRIM(B4)="Sany",TRIM(B4)="Komatsu"),"Dumper",IF(TRIM(B4)="Excavator","Excavator",IF(OR(TRIM(B4)="Front End Loader",TRIM(B4)="Fel"),"Front End Loader",IF(OR(TRIM(B4)="Surface Miner",TRIM(B4)="Csm"),"Surface Miner",IF(TRIM(B4)="Diesel Bowser","Diesel Bowser","Other")))))) -> Tipper | AD4: =IF(E4=0,"Non-Operational","Operational") -> Non-Operational | AE4: =IF(OR(C4=54,C4=67,C4=10,C4=16,C4=6,C4=12,C4=28),"Aggregate","Individual") -> Individual
A5: 3 | B5: Tipper | C5: V-238 | D5: 712.9178 | E5: 151.592 | F5: 72.0888 | G5: 71.1759 | H5: 561.3258 | I5: 8.8303 | J5: 79.5032 | K5: 19.7745 | L5: 71.1759 | M5: 28.6048 | N5: 99.7807 | O5: 0.21263602 | P5: 0.4695228 | Q5: 34 | R5: 777.36 | S5: 22.863529 | T5: 17 | U5: =T5*V5 -> 221 | V5: 13 | W5: 834.44 | X5: 8.3627395 | Y5: 595.22551 | Z5: 239.21449 | AA5: 16.361569 | AB5: 0.83581073 | AC5: =IF(OR(TRIM(B5)="Tipper",TRIM(B5)="Volvo",TRIM(B5)="Bharatbenz"),"Tipper",IF(OR(TRIM(B5)="Dumper",TRIM(B5)="Sany",TRIM(B5)="Komatsu"),"Dumper",IF(TRIM(B5)="Excavator","Excavator",IF(OR(TRIM(B5)="Front End Loader",TRIM(B5)="Fel"),"Front End Loader",IF(OR(TRIM(B5)="Surface Miner",TRIM(B5)="Csm"),"Surface Miner",IF(TRIM(B5)="Diesel Bowser","Diesel Bowser","Other")))))) -> Tipper | AD5: =IF(E5=0,"Non-Operational","Operational") -> Operational | AE5: =IF(OR(C5=54,C5=67,C5=10,C5=16,C5=6,C5=12,C5=28),"Aggregate","Individual") -> Individual
A6: 4 | B6: Tipper | C6: V-246 | D6: 720 | E6: 0 | F6: 0 | G6: 0 | H6: 720 | I6: 0 | J6: 0 | K6: 0 | L6: 0 | M6: 0 | N6: 0 | O6: 0 | P6: 0 | Q6: 0 | R6: 0 | S6: 0 | T6: 0 | U6: =T6*V6 -> 0 | V6: 13 | W6: 0 | X6: 0 | Y6: 0 | Z6: 0 | AA6: 0 | AB6: 0 | AC6: =IF(OR(TRIM(B6)="Tipper",TRIM(B6)="Volvo",TRIM(B6)="Bharatbenz"),"Tipper",IF(OR(TRIM(B6)="Dumper",TRIM(B6)="Sany",TRIM(B6)="Komatsu"),"Dumper",IF(TRIM(B6)="Excavator","Excavator",IF(OR(TRIM(B6)="Front End Loader",TRIM(B6)="Fel"),"Front End Loader",IF(OR(TRIM(B6)="Surface Miner",TRIM(B6)="Csm"),"Surface Miner",IF(TRIM(B6)="Diesel Bowser","Diesel Bowser","Other")))))) -> Tipper | AD6: =IF(E6=0,"Non-Operational","Operational") -> Non-Operational | AE6: =IF(OR(C6=54,C6=67,C6=10,C6=16,C6=6,C6=12,C6=28),"Aggregate","Individual") -> Individual
A7: 5 | B7: Tipper | C7: V-260 | D7: 720.0003 | E7: 26.4897 | F7: 6.1477 | G7: 5.2485 | H7: 693.5106 | I7: 3.7032 | J7: 20.342 | K7: 9.2225 | L7: 5.2485 | M7: 12.9257 | N7: 18.1742 | O7: 0.036791235 | P7: 0.19813361 | Q7: 0 | R7: 0 | S7: 0 | T7: 1 | U7: =T7*V7 -> 13 | V7: 13 | W7: 386.84 | X7: 21.285118 | Y7: 111.71494 | Z7: 275.12506 | AA7: 0 | AB7: 0 | AC7: =IF(OR(TRIM(B7)="Tipper",TRIM(B7)="Volvo",TRIM(B7)="Bharatbenz"),"Tipper",IF(OR(TRIM(B7)="Dumper",TRIM(B7)="Sany",TRIM(B7)="Komatsu"),"Dumper",IF(TRIM(B7)="Excavator","Excavator",IF(OR(TRIM(B7)="Front End Loader",TRIM(B7)="Fel"),"Front End Loader",IF(OR(TRIM(B7)="Surface Miner",TRIM(B7)="Csm"),"Surface Miner",IF(TRIM(B7)="Diesel Bowser","Diesel Bowser","Other")))))) -> Tipper | AD7: =IF(E7=0,"Non-Operational","Operational") -> Operational | AE7: =IF(OR(C7=54,C7=67,C7=10,C7=16,C7=6,C7=12,C7=28),"Aggregate","Individual") -> Individual
A8: 6 | B8: Tipper | C8: V-263 | D8: 720 | E8: 115.5897 | F8: 22.691 | G8: 21.2176 | H8: 604.4103 | I8: 2.7918 | J8: 92.8987 | K8: 0.3882 | L8: 21.2176 | M8: 3.18 | N8: 24.3976 | O8: 0.16054125 | P8: 0.18355961 | Q8: 8 | R8: 193.28 | S8: 24.16 | T8: 1 | U8: =T8*V8 -> 13 | V8: 13 | W8: 280.39 | X8: 11.492524 | Y8: 243.84377 | Z8: 36.546226 | AA8: 31.154444 | AB8: 1.359269 | AC8: =IF(OR(TRIM(B8)="Tipper",TRIM(B8)="Volvo",TRIM(B8)="Bharatbenz"),"Tipper",IF(OR(TRIM(B8)="Dumper",TRIM(B8)="Sany",TRIM(B8)="Komatsu"),"Dumper",IF(TRIM(B8)="Excavator","Excavator",IF(OR(TRIM(B8)="Front End Loader",TRIM(B8)="Fel"),"Front End Loader",IF(OR(TRIM(B8)="Surface Miner",TRIM(B8)="Csm"),"Surface Miner",IF(TRIM(B8)="Diesel Bowser","Diesel Bowser","Other")))))) -> Tipper | AD8: =IF(E8=0,"Non-Operational","Operational") -> Operational | AE8: =IF(OR(C8=54,C8=67,C8=10,C8=16,C8=6,C8=12,C8=28),"Aggregate","Individual") -> Individual
A9: 7 | B9: Tipper | C9: V-266 | D9: 720 | E9: 0 | F9: 0 | G9: 0 | H9: 720 | I9: 0 | J9: 0 | K9: 0 | L9: 0 | M9: 0 | N9: 0 | O9: 0 | P9: 0 | Q9: 0 | R9: 0 | S9: 0 | T9: 0 | U9: =T9*V9 -> 0 | V9: 13 | W9: 0 | X9: 0 | Y9: 0 | Z9: 0 | AA9: 0 | AB9: 0 | AC9: =IF(OR(TRIM(B9)="Tipper",TRIM(B9)="Volvo",TRIM(B9)="Bharatbenz"),"Tipper",IF(OR(TRIM(B9)="Dumper",TRIM(B9)="Sany",TRIM(B9)="Komatsu"),"Dumper",IF(TRIM(B9)="Excavator","Excavator",IF(OR(TRIM(B9)="Front End Loader",TRIM(B9)="Fel"),"Front End Loader",IF(OR(TRIM(B9)="Surface Miner",TRIM(B9)="Csm"),"Surface Miner",IF(TRIM(B9)="Diesel Bowser","Diesel Bowser","Other")))))) -> Tipper | AD9: =IF(E9=0,"Non-Operational","Operational") -> Non-Operational | AE9: =IF(OR(C9=54,C9=67,C9=10,C9=16,C9=6,C9=12,C9=28),"Aggregate","Individual") -> Individual
A10: 8 | B10: Tipper | C10: V-267 | D10: 719.9997 | E10: 260.4761 | F10: 12.0065 | G10: 11.0087 | H10: 459.5236 | I10: 5.5453 | J10: 248.4696 | K10: 9.7536 | L10: 11.0087 | M10: 15.2989 | N10: 26.3076 | O10: 0.36177251 | P10: 0.042263762 | Q10: 0 | R10: 0 | S10: 0 | T10: 2 | U10: =T10*V10 -> 26 | V10: 13 | W10: 418.51 | X10: 15.908331 | Y10: 175.13004 | Z10: 243.37996 | AA10: 0 | AB10: 0 | AC10: =IF(OR(TRIM(B10)="Tipper",TRIM(B10)="Volvo",TRIM(B10)="Bharatbenz"),"Tipper",IF(OR(TRIM(B10)="Dumper",TRIM(B10)="Sany",TRIM(B10)="Komatsu"),"Dumper",IF(TRIM(B10)="Excavator","Excavator",IF(OR(TRIM(B10)="Front End Loader",TRIM(B10)="Fel"),"Front End Loader",IF(OR(TRIM(B10)="Surface Miner",TRIM(B10)="Csm"),"Surface Miner",IF(TRIM(B10)="Diesel Bowser","Diesel Bowser","Other")))))) -> Tipper | AD10: =IF(E10=0,"Non-Operational","Operational") -> Operational | AE10: =IF(OR(C10=54,C10=67,C10=10,C10=16,C10=6,C10=12,C10=28),"Aggregate","Individual") -> Individual
A11: 9 | B11: Tipper | C11: V-273 | D11: 712.672 | E11: 406.49 | F11: 289.602 | G11: 64.5774 | H11: 306.182 | I11: 5.8293 | J11: 116.888 | K11: 3.2562 | L11: 64.5774 | M11: 9.0855 | N11: 73.6629 | O11: 0.57037459 | P11: 0.1588659 | Q11: 38 | R11: 891.32 | S11: 23.455789 | T11: 36 | U11: =T11*V11 -> 468 | V11: 13 | W11: 739.99 | X11: 10.045627 | Y11: 648.72046 | Z11: 91.269542 | AA11: 9.9998649 | AB11: 0.54438249 | AC11: =IF(OR(TRIM(B11)="Tipper",TRIM(B11)="Volvo",TRIM(B11)="Bharatbenz"),"Tipper",IF(OR(TRIM(B11)="Dumper",TRIM(B11)="Sany",TRIM(B11)="Komatsu"),"Dumper",IF(TRIM(B11)="Excavator","Excavator",IF(OR(TRIM(B11)="Front End Loader",TRIM(B11)="Fel"),"Front End Loader",IF(OR(TRIM(B11)="Surface Miner",TRIM(B11)="Csm"),"Surface Miner",IF(TRIM(B11)="Diesel Bowser","Diesel Bowser","Other")))))) -> Tipper | AD11: =IF(E11=0,"Non-Operational","Operational") -> Operational | AE11: =IF(OR(C11=54,C11=67,C11=10,C11=16,C11=6,C11=12,C11=28),"Aggregate","Individual") -> Individual
A12: 10 | B12: Tipper | C12: V-274 | D12: 720.0001 | E12: 0.0306 | F12: 0.0306 | G12: 0.0293 | H12: 719.9695 | I12: 0 | J12: 0 | K12: 4.6001 | L12: 0.0293 | M12: 4.6001 | N12: 4.6294 | O12: 4.25e-05 | P12: 0.95751634 | Q12: 0 | R12: 0 | S12: 0 | T12: 0 | U12: =T12*V12 -> 0 | V12: 13 | W12: 0 | X12: 0 | Y12: 0 | Z12: 0 | AA12: 0 | AB12: 0 | AC12: =IF(OR(TRIM(B12)="Tipper",TRIM(B12)="Volvo",TRIM(B12)="Bharatbenz"),"Tipper",IF(OR(TRIM(B12)="Dumper",TRIM(B12)="Sany",TRIM(B12)="Komatsu"),"Dumper",IF(TRIM(B12)="Excavator","Excavator",IF(OR(TRIM(B12)="Front End Loader",TRIM(B12)="Fel"),"Front End Loader",IF(OR(TRIM(B12)="Surface Miner",TRIM(B12)="Csm"),"Surface Miner",IF(TRIM(B12)="Diesel Bowser","Diesel Bowser","Other")))))) -> Tipper | AD12: =IF(E12=0,"Non-Operational","Operational") -> Operational | AE12: =IF(OR(C12=54,C12=67,C12=10,C12=16,C12=6,C12=12,C12=28),"Aggregate","Individual") -> Individual
A13: 11 | B13: Tipper | C13: V-275 | D13: 720.0001 | E13: 0.1572 | F13: 0.1572 | G13: 0.1549 | H13: 719.8429 | I13: 0 | J13: 0 | K13: 12.2297 | L13: 0.1549 | M13: 12.2297 | N13: 12.3846 | O13: 0.0002183333 | P13: 0.98536896 | Q13: 0 | R13: 0 | S13: 0 | T13: 0 | U13: =T13*V13 -> 0 | V13: 13 | W13: 0 | X13: 0 | Y13: 0 | Z13: 0 | AA13: 0 | AB13: 0 | AC13: =IF(OR(TRIM(B13)="Tipper",TRIM(B13)="Volvo",TRIM(B13)="Bharatbenz"),"Tipper",IF(OR(TRIM(B13)="Dumper",TRIM(B13)="Sany",TRIM(B13)="Komatsu"),"Dumper",IF(TRIM(B13)="Excavator","Excavator",IF(OR(TRIM(B13)="Front End Loader",TRIM(B13)="Fel"),"Front End Loader",IF(OR(TRIM(B13)="Surface Miner",TRIM(B13)="Csm"),"Surface Miner",IF(TRIM(B13)="Diesel Bowser","Diesel Bowser","Other")))))) -> Tipper | AD13: =IF(E13=0,"Non-Operational","Operational") -> Operational | AE13: =IF(OR(C13=54,C13=67,C13=10,C13=16,C13=6,C13=12,C13=28),"Aggregate","Individual") -> Individual
A14: 12 | B14: Tipper | C14: V-283 | D14: 719.9999 | E14: 0.0347 | F14: 0.0347 | G14: 0.0333 | H14: 719.9652 | I14: 0 | J14: 0 | K14: 0.1167 | L14: 0.0333 | M14: 0.1167 | N14: 0.15 | O14: 4.81945e-05 | P14: 0.95965418 | Q14: 0 | R14: 0 | S14: 0 | T14: 0 | U14: =T14*V14 -> 0 | V14: 13 | W14: 0 | X14: 0 | Y14: 0 | Z14: 0 | AA14: 0 | AB14: 0 | AC14: =IF(OR(TRIM(B14)="Tipper",TRIM(B14)="Volvo",TRIM(B14)="Bharatbenz"),"Tipper",IF(OR(TRIM(B14)="Dumper",TRIM(B14)="Sany",TRIM(B14)="Komatsu"),"Dumper",IF(TRIM(B14)="Excavator","Excavator",IF(OR(TRIM(B14)="Front End Loader",TRIM(B14)="Fel"),"Front End Loader",IF(OR(TRIM(B14)="Surface Miner",TRIM(B14)="Csm"),"Surface Miner",IF(TRIM(B14)="Diesel Bowser","Diesel Bowser","Other")))))) -> Tipper | AD14: =IF(E14=0,"Non-Operational","Operational") -> Operational | AE14: =IF(OR(C14=54,C14=67,C14=10,C14=16,C14=6,C14=12,C14=28),"Aggregate","Individual") -> Individual
A15: 1 | B15: Volvo | C15: 12 | D15: 718.79916 | E15: 80.076642 | F15: 33.568183 | G15: 14.458775 | H15: 638.72252 | I15: 2.2249917 | J15: 46.508458 | K15: 9.2433 | L15: 14.458775 | M15: 11.468292 | N15: 25.927067 | O15: 0.11140336 | P15: 0.18056171 | Q15: 80 | R15: 1861.96 | S15: 23.2745 | T15: 57 | U15: =T15*V15 -> 741 | V15: 13 | W15: 532.034 | X15: 13.418868 | Y15: 354.92695 | Z15: 177.10705 | AA15: 19.171959 | AB15: 0.91315406 | AC15: =IF(OR(TRIM(B15)="Tipper",TRIM(B15)="Volvo",TRIM(B15)="Bharatbenz"),"Tipper",IF(OR(TRIM(B15)="Dumper",TRIM(B15)="Sany",TRIM(B15)="Komatsu"),"Dumper",IF(TRIM(B15)="Excavator","Excavator",IF(OR(TRIM(B15)="Front End Loader",TRIM(B15)="Fel"),"Front End Loader",IF(OR(TRIM(B15)="Surface Miner",TRIM(B15)="Csm"),"Surface Miner",IF(TRIM(B15)="Diesel Bowser","Diesel Bowser","Other")))))) -> Tipper | AD15: =IF(E15=0,"Non-Operational","Operational") -> Operational | AE15: =IF(OR(C15=54,C15=67,C15=10,C15=16,C15=6,C15=12,C15=28),"Aggregate","Individual") -> Aggregate
A16: 1 | B16: Tipper | C16: BB-358 | D16: 720.0006 | E16: 654.5274 | F16: 204.9314 | G16: 202.041 | H16: 65.4732 | I16: 11.0411 | J16: 449.596 | K16: 8.1412 | L16: 202.041 | M16: 19.1823 | N16: 221.2233 | O16: 0.90906508 | P16: 0.30868226 | Q16: 646 | R16: 24054.75 | S16: 37.236455 | T16: 13 | U16: =T16*V16 -> 169 | V16: 13 | W16: 4668.05 | X16: 21.101078 | Y16: 4263.2828 | Z16: 404.7672 | AA16: 7.0835357 | AB16: 0.19270551 | AC16: =IF(OR(TRIM(B16)="Tipper",TRIM(B16)="Volvo",TRIM(B16)="Bharatbenz"),"Tipper",IF(OR(TRIM(B16)="Dumper",TRIM(B16)="Sany",TRIM(B16)="Komatsu"),"Dumper",IF(TRIM(B16)="Excavator","Excavator",IF(OR(TRIM(B16)="Front End Loader",TRIM(B16)="Fel"),"Front End Loader",IF(OR(TRIM(B16)="Surface Miner",TRIM(B16)="Csm"),"Surface Miner",IF(TRIM(B16)="Diesel Bowser","Diesel Bowser","Other")))))) -> Tipper | AD16: =IF(E16=0,"Non-Operational","Operational") -> Operational | AE16: =IF(OR(C16=54,C16=67,C16=10,C16=16,C16=6,C16=12,C16=28),"Aggregate","Individual") -> Individual
A17: 2 | B17: Tipper | C17: BB-396 | D17: 720 | E17: 720 | F17: 720 | G17: 0 | H17: 0 | I17: 0 | J17: 0 | K17: 0 | L17: 0 | M17: 0 | N17: 0 | O17: 1 | P17: 0 | Q17: 0 | R17: 0 | S17: 0 | T17: 0 | U17: =T17*V17 -> 0 | V17: 13 | W17: 40.62 | X17: 0 | Y17: 0 | Z17: 0 | AA17: 0 | AB17: 0 | AC17: =IF(OR(TRIM(B17)="Tipper",TRIM(B17)="Volvo",TRIM(B17)="Bharatbenz"),"Tipper",IF(OR(TRIM(B17)="Dumper",TRIM(B17)="Sany",TRIM(B17)="Komatsu"),"Dumper",IF(TRIM(B17)="Excavator","Excavator",IF(OR(TRIM(B17)="Front End Loader",TRIM(B17)="Fel"),"Front End Loader",IF(OR(TRIM(B17)="Surface Miner",TRIM(B17)="Csm"),"Surface Miner",IF(TRIM(B17)="Diesel Bowser","Diesel Bowser","Other")))))) -> Tipper | AD17: =IF(E17=0,"Non-Operational","Operational") -> Operational | AE17: =IF(OR(C17=54,C17=67,C17=10,C17=16,C17=6,C17=12,C17=28),"Aggregate","Individual") -> Individual
A18: 3 | B18: Tipper | C18: BB-397 | D18: 720.0002 | E18: 451.475 | F18: 80.972 | G18: 80.0758 | H18: 268.5252 | I18: 2.1516 | J18: 370.503 | K18: 1.6821 | L18: 80.0758 | M18: 3.8337 | N18: 83.9095 | O18: 0.62704844 | P18: 0.17736486 | Q18: 271 | R18: 9895.45 | S18: 36.514576 | T18: 9 | U18: =T18*V18 -> 117 | V18: 13 | W18: 1881.11 | X18: 22.41832 | Y18: 1795.1649 | Z18: 85.945112 | AA18: 6.71825 | AB18: 0.18787709 | AC18: =IF(OR(TRIM(B18)="Tipper",TRIM(B18)="Volvo",TRIM(B18)="Bharatbenz"),"Tipper",IF(OR(TRIM(B18)="Dumper",TRIM(B18)="Sany",TRIM(B18)="Komatsu"),"Dumper",IF(TRIM(B18)="Excavator","Excavator",IF(OR(TRIM(B18)="Front End Loader",TRIM(B18)="Fel"),"Front End Loader",IF(OR(TRIM(B18)="Surface Miner",TRIM(B18)="Csm"),"Surface Miner",IF(TRIM(B18)="Diesel Bowser","Diesel Bowser","Other")))))) -> Tipper | AD18: =IF(E18=0,"Non-Operational","Operational") -> Operational | AE18: =IF(OR(C18=54,C18=67,C18=10,C18=16,C18=6,C18=12,C18=28),"Aggregate","Individual") -> Individual
A19: 4 | B19: Tipper | C19: BB-398 | D19: 720.0013 | E19: 650.6226 | F19: 293.9854 | G19: 291.2517 | H19: 69.3787 | I19: 12.4835 | J19: 356.6372 | K19: 4.3856 | L19: 291.2517 | M19: 16.8691 | N19: 308.1208 | O19: 0.90364087 | P19: 0.44765076 | Q19: 645 | R19: 23629.83 | S19: 36.635395 | T19: 16 | U19: =T19*V19 -> 208 | V19: 13 | W19: 4732.44 | X19: 15.359041 | Y19: 4473.3468 | Z19: 259.0932 | AA19: 7.1595159 | AB19: 0.19852646 | AC19: =IF(OR(TRIM(B19)="Tipper",TRIM(B19)="Volvo",TRIM(B19)="Bharatbenz"),"Tipper",IF(OR(TRIM(B19)="Dumper",TRIM(B19)="Sany",TRIM(B19)="Komatsu"),"Dumper",IF(TRIM(B19)="Excavator","Excavator",IF(OR(TRIM(B19)="Front End Loader",TRIM(B19)="Fel"),"Front End Loader",IF(OR(TRIM(B19)="Surface Miner",TRIM(B19)="Csm"),"Surface Miner",IF(TRIM(B19)="Diesel Bowser","Diesel Bowser","Other")))))) -> Tipper | AD19: =IF(E19=0,"Non-Operational","Operational") -> Operational | AE19: =IF(OR(C19=54,C19=67,C19=10,C19=16,C19=6,C19=12,C19=28),"Aggregate","Individual") -> Individual
A20: 5 | B20: Tipper | C20: BB-399 | D20: 720 | E20: 0 | F20: 0 | G20: 0 | H20: 720 | I20: 0 | J20: 0 | K20: 0 | L20: 0 | M20: 0 | N20: 0 | O20: 0 | P20: 0 | Q20: 0 | R20: 0 | S20: 0 | T20: 0 | U20: =T20*V20 -> 0 | V20: 13 | W20: 0 | X20: 0 | Y20: 0 | Z20: 0 | AA20: 0 | AB20: 0 | AC20: =IF(OR(TRIM(B20)="Tipper",TRIM(B20)="Volvo",TRIM(B20)="Bharatbenz"),"Tipper",IF(OR(TRIM(B20)="Dumper",TRIM(B20)="Sany",TRIM(B20)="Komatsu"),"Dumper",IF(TRIM(B20)="Excavator","Excavator",IF(OR(TRIM(B20)="Front End Loader",TRIM(B20)="Fel"),"Front End Loader",IF(OR(TRIM(B20)="Surface Miner",TRIM(B20)="Csm"),"Surface Miner",IF(TRIM(B20)="Diesel Bowser","Diesel Bowser","Other")))))) -> Tipper | AD20: =IF(E20=0,"Non-Operational","Operational") -> Non-Operational | AE20: =IF(OR(C20=54,C20=67,C20=10,C20=16,C20=6,C20=12,C20=28),"Aggregate","Individual") -> Individual
A21: 6 | B21: Tipper | C21: BB-400 | D21: 720.0029 | E21: 521.6522 | F21: 223.344 | G21: 222.0431 | H21: 198.3507 | I21: 5.605 | J21: 298.3082 | K21: 0.6612 | L21: 222.0431 | M21: 6.2662 | N21: 228.3093 | O21: 0.72451403 | P21: 0.42565353 | Q21: 465 | R21: 16923.51 | S21: 36.394645 | T21: 14 | U21: =T21*V21 -> 182 | V21: 13 | W21: 3173.74 | X21: 13.901054 | Y21: 3086.6332 | Z21: 87.106787 | AA21: 6.625762 | AB21: 0.18553905 | AC21: =IF(OR(TRIM(B21)="Tipper",TRIM(B21)="Volvo",TRIM(B21)="Bharatbenz"),"Tipper",IF(OR(TRIM(B21)="Dumper",TRIM(B21)="Sany",TRIM(B21)="Komatsu"),"Dumper",IF(TRIM(B21)="Excavator","Excavator",IF(OR(TRIM(B21)="Front End Loader",TRIM(B21)="Fel"),"Front End Loader",IF(OR(TRIM(B21)="Surface Miner",TRIM(B21)="Csm"),"Surface Miner",IF(TRIM(B21)="Diesel Bowser","Diesel Bowser","Other")))))) -> Tipper | AD21: =IF(E21=0,"Non-Operational","Operational") -> Operational | AE21: =IF(OR(C21=54,C21=67,C21=10,C21=16,C21=6,C21=12,C21=28),"Aggregate","Individual") -> Individual
A22: 7 | B22: Tipper | C22: BB-401 | D22: 720.0014 | E22: 150.8831 | F22: 83.8367 | G22: 81.3734 | H22: 569.1183 | I22: 1.1792 | J22: 67.0464 | K22: 1.7364 | L22: 81.3734 | M22: 2.9156 | N22: 84.289 | O22: 0.20955945 | P22: 0.53931421 | Q22: 151 | R22: 5633.1 | S22: 37.305298 | T22: 1 | U22: =T22*V22 -> 13 | V22: 13 | W22: 998.02 | X22: 11.840454 | Y22: 963.49797 | Z22: 34.522027 | AA22: 6.5659211 | AB22: 0.17676272 | AC22: =IF(OR(TRIM(B22)="Tipper",TRIM(B22)="Volvo",TRIM(B22)="Bharatbenz"),"Tipper",IF(OR(TRIM(B22)="Dumper",TRIM(B22)="Sany",TRIM(B22)="Komatsu"),"Dumper",IF(TRIM(B22)="Excavator","Excavator",IF(OR(TRIM(B22)="Front End Loader",TRIM(B22)="Fel"),"Front End Loader",IF(OR(TRIM(B22)="Surface Miner",TRIM(B22)="Csm"),"Surface Miner",IF(TRIM(B22)="Diesel Bowser","Diesel Bowser","Other")))))) -> Tipper | AD22: =IF(E22=0,"Non-Operational","Operational") -> Operational | AE22: =IF(OR(C22=54,C22=67,C22=10,C22=16,C22=6,C22=12,C22=28),"Aggregate","Individual") -> Individual
A23: 8 | B23: Tipper | C23: BB-402 | D23: 720.0005 | E23: 611.9036 | F23: 342.7396 | G23: 337.5977 | H23: 108.0969 | I23: 7.1208 | J23: 269.164 | K23: 3.1264 | L23: 337.5977 | M23: 10.2472 | N23: 347.8449 | O23: 0.84986552 | P23: 0.55171713 | Q23: 679 | R23: 24977.95 | S23: 36.786377 | T23: 17 | U23: =T23*V23 -> 221 | V23: 13 | W23: 4428.51 | X23: 12.731278 | Y23: 4298.0501 | Z23: 130.45995 | AA23: 6.3628017 | AB23: 0.17574185 | AC23: =IF(OR(TRIM(B23)="Tipper",TRIM(B23)="Volvo",TRIM(B23)="Bharatbenz"),"Tipper",IF(OR(TRIM(B23)="Dumper",TRIM(B23)="Sany",TRIM(B23)="Komatsu"),"Dumper",IF(TRIM(B23)="Excavator","Excavator",IF(OR(TRIM(B23)="Front End Loader",TRIM(B23)="Fel"),"Front End Loader",IF(OR(TRIM(B23)="Surface Miner",TRIM(B23)="Csm"),"Surface Miner",IF(TRIM(B23)="Diesel Bowser","Diesel Bowser","Other")))))) -> Tipper | AD23: =IF(E23=0,"Non-Operational","Operational") -> Operational | AE23: =IF(OR(C23=54,C23=67,C23=10,C23=16,C23=6,C23=12,C23=28),"Aggregate","Individual") -> Individual
A24: 9 | B24: Tipper | C24: BB-404 | D24: 719.9999 | E24: 52.528 | F24: 10.5343 | G24: 8.5302 | H24: 667.4719 | I24: 1.0713 | J24: 41.9937 | K24: 0.4264 | L24: 8.5302 | M24: 1.4977 | N24: 10.0279 | O24: 0.072955566 | P24: 0.16239339 | Q24: 1 | R24: 35.28 | S24: 35.28 | T24: 4 | U24: =T24*V24 -> 52 | V24: 13 | W24: 180.95 | X24: 18.044655 | Y24: 153.92452 | Z24: 27.02548 | AA24: 36.19 | AB24: 2.0732126 | AC24: =IF(OR(TRIM(B24)="Tipper",TRIM(B24)="Volvo",TRIM(B24)="Bharatbenz"),"Tipper",IF(OR(TRIM(B24)="Dumper",TRIM(B24)="Sany",TRIM(B24)="Komatsu"),"Dumper",IF(TRIM(B24)="Excavator","Excavator",IF(OR(TRIM(B24)="Front End Loader",TRIM(B24)="Fel"),"Front End Loader",IF(OR(TRIM(B24)="Surface Miner",TRIM(B24)="Csm"),"Surface Miner",IF(TRIM(B24)="Diesel Bowser","Diesel Bowser","Other")))))) -> Tipper | AD24: =IF(E24=0,"Non-Operational","Operational") -> Operational | AE24: =IF(OR(C24=54,C24=67,C24=10,C24=16,C24=6,C24=12,C24=28),"Aggregate","Individual") -> Individual
A25: 10 | B25: Tipper | C25: BB-407 | D25: 720.0011 | E25: 501.6495 | F25: 205.4507 | G25: 202.5171 | H25: 218.3516 | I25: 6.8215 | J25: 296.1988 | K25: 14.2458 | L25: 202.5171 | M25: 21.0673 | N25: 223.5844 | O25: 0.69673435 | P25: 0.40370239 | Q25: 438 | R25: 15854.01 | S25: 36.19637 | T25: 12 | U25: =T25*V25 -> 156 | V25: 13 | W25: 3339.07 | X25: 14.934271 | Y25: 3024.4452 | Z25: 314.62477 | AA25: 7.4201556 | AB25: 0.20856139 | AC25: =IF(OR(TRIM(B25)="Tipper",TRIM(B25)="Volvo",TRIM(B25)="Bharatbenz"),"Tipper",IF(OR(TRIM(B25)="Dumper",TRIM(B25)="Sany",TRIM(B25)="Komatsu"),"Dumper",IF(TRIM(B25)="Excavator","Excavator",IF(OR(TRIM(B25)="Front End Loader",TRIM(B25)="Fel"),"Front End Loader",IF(OR(TRIM(B25)="Surface Miner",TRIM(B25)="Csm"),"Surface Miner",IF(TRIM(B25)="Diesel Bowser","Diesel Bowser","Other")))))) -> Tipper | AD25: =IF(E25=0,"Non-Operational","Operational") -> Operational | AE25: =IF(OR(C25=54,C25=67,C25=10,C25=16,C25=6,C25=12,C25=28),"Aggregate","Individual") -> Individual
A26: 11 | B26: Tipper | C26: BB-410 | D26: 720.0011 | E26: 582.8098 | F26: 202.7991 | G26: 199.4988 | H26: 137.1913 | I26: 18.8576 | J26: 380.0107 | K26: 13.7533 | L26: 199.4988 | M26: 32.6109 | N26: 232.1097 | O26: 0.80945682 | P26: 0.34230516 | Q26: 167 | R26: 6181.65 | S26: 37.015868 | T26: 120 | U26: =T26*V26 -> 1560 | V26: 13 | W26: 2394.96 | X26: 10.318225 | Y26: 2058.4734 | Z26: 336.48659 | AA26: 8.3448084 | AB26: 0.30936041 | AC26: =IF(OR(TRIM(B26)="Tipper",TRIM(B26)="Volvo",TRIM(B26)="Bharatbenz"),"Tipper",IF(OR(TRIM(B26)="Dumper",TRIM(B26)="Sany",TRIM(B26)="Komatsu"),"Dumper",IF(TRIM(B26)="Excavator","Excavator",IF(OR(TRIM(B26)="Front End Loader",TRIM(B26)="Fel"),"Front End Loader",IF(OR(TRIM(B26)="Surface Miner",TRIM(B26)="Csm"),"Surface Miner",IF(TRIM(B26)="Diesel Bowser","Diesel Bowser","Other")))))) -> Tipper | AD26: =IF(E26=0,"Non-Operational","Operational") -> Operational | AE26: =IF(OR(C26=54,C26=67,C26=10,C26=16,C26=6,C26=12,C26=28),"Aggregate","Individual") -> Individual
A27: 12 | B27: Tipper | C27: BB-412 | D27: 720.0001 | E27: 1.1092 | F27: 1.1092 | G27: 1.0325 | H27: 718.8909 | I27: 0 | J27: 0 | K27: 4.3652 | L27: 1.0325 | M27: 4.3652 | N27: 5.3977 | O27: 0.0015405553 | P27: 0.93085106 | Q27: 1 | R27: 35.82 | S27: 35.82 | T27: 0 | U27: =T27*V27 -> 0 | V27: 13 | W27: 0 | X27: 0 | Y27: 0 | Z27: 0 | AA27: 0 | AB27: 0 | AC27: =IF(OR(TRIM(B27)="Tipper",TRIM(B27)="Volvo",TRIM(B27)="Bharatbenz"),"Tipper",IF(OR(TRIM(B27)="Dumper",TRIM(B27)="Sany",TRIM(B27)="Komatsu"),"Dumper",IF(TRIM(B27)="Excavator","Excavator",IF(OR(TRIM(B27)="Front End Loader",TRIM(B27)="Fel"),"Front End Loader",IF(OR(TRIM(B27)="Surface Miner",TRIM(B27)="Csm"),"Surface Miner",IF(TRIM(B27)="Diesel Bowser","Diesel Bowser","Other")))))) -> Tipper | AD27: =IF(E27=0,"Non-Operational","Operational") -> Operational | AE27: =IF(OR(C27=54,C27=67,C27=10,C27=16,C27=6,C27=12,C27=28),"Aggregate","Individual") -> Individual
... A69: 54 | B69: Tipper | C69: BB-594 | D69: 720.0017 | E69: 610.7623 | F69: 378.4787 | G69: 371.8242 | H69: 109.2394 | I69: 12.0654 | J69: 232.2836 | K69: 0.3014 | L69: 371.8242 | M69: 12.3668 | N69: 384.191 | O69: 0.84827897 | P69: 0.60878708 | Q69: 949 | R69: 33780.29 | S69: 35.595669 | T69: 11 | U69: =T69*V69 -> 143 | V69: 13 | W69: 5309.29 | X69: 13.819402 | Y69: 5138.3882 | Z69: 170.90178 | AA69: 5.5305104 | AB69: 0.1565087 | AC69: =IF(OR(TRIM(B69)="Tipper",TRIM(B69)="Volvo",TRIM(B69)="Bharatbenz"),"Tipper",IF(OR(TRIM(B69)="Dumper",TRIM(B69)="Sany",TRIM(B69)="Komatsu"),"Dumper",IF(TRIM(B69)="Excavator","Excavator",IF(OR(TRIM(B69)="Front End Loader",TRIM(B69)="Fel"),"Front End Loader",IF(OR(TRIM(B69)="Surface Miner",TRIM(B69)="Csm"),"Surface Miner",IF(TRIM(B69)="Diesel Bowser","Diesel Bowser","Other")))))) -> Tipper | AD69: =IF(E69=0,"Non-Operational","Operational") -> Operational | AE69: =IF(OR(C69=54,C69=67,C69=10,C69=16,C69=6,C69=12,C69=28),"Aggregate","Individual") -> Individual
A70: 2 | B70: Bharatbenz | C70: 54 | D70: 719.75317 | E70: 505.63915 | F70: 248.41587 | G70: 218.05491 | H70: 214.11402 | I70: 8.4906296 | J70: 257.22328 | K70: 6.0812056 | L70: 218.05491 | M70: 14.571835 | N70: 232.62675 | O70: 0.70251743 | P70: 0.43124611 | Q70: 27660 | R70: 1005442.3 | S70: 36.350048 | T70: 838 | U70: =T70*V70 -> 10894 | V70: 13 | W70: 3673.2206 | X70: 15.204809 | Y70: 3491.7476 | Z70: 227.94077 | AA70: 7.3371633 | AB70: 0.2307315 | AC70: =IF(OR(TRIM(B70)="Tipper",TRIM(B70)="Volvo",TRIM(B70)="Bharatbenz"),"Tipper",IF(OR(TRIM(B70)="Dumper",TRIM(B70)="Sany",TRIM(B70)="Komatsu"),"Dumper",IF(TRIM(B70)="Excavator","Excavator",IF(OR(TRIM(B70)="Front End Loader",TRIM(B70)="Fel"),"Front End Loader",IF(OR(TRIM(B70)="Surface Miner",TRIM(B70)="Csm"),"Surface Miner",IF(TRIM(B70)="Diesel Bowser","Diesel Bowser","Other")))))) -> Tipper | AD70: =IF(E70=0,"Non-Operational","Operational") -> Operational | AE70: =IF(OR(C70=54,C70=67,C70=10,C70=16,C70=6,C70=12,C70=28),"Aggregate","Individual") -> Aggregate
A71: 1 | B71: Dumper | C71: S-034 | D71: 719.9997 | E71: 229.5383 | F71: 117.0169 | G71: 111.5582 | H71: 490.4614 | I71: 6.685 | J71: 112.5214 | K71: 4.7652 | L71: 111.5582 | M71: 11.4502 | N71: 123.0084 | O71: 0.31880333 | P71: 0.48601127 | Q71: 0 | R71: 0 | S71: 0 | T71: 406 | U71: =T71*V71 -> 10150 | V71: 25 | W71: 4198.17 | X71: 34.129133 | Y71: 3807.3846 | Z71: 390.78539 | AA71: 0 | AB71: 0 | AC71: =IF(OR(TRIM(B71)="Tipper",TRIM(B71)="Volvo",TRIM(B71)="Bharatbenz"),"Tipper",IF(OR(TRIM(B71)="Dumper",TRIM(B71)="Sany",TRIM(B71)="Komatsu"),"Dumper",IF(TRIM(B71)="Excavator","Excavator",IF(OR(TRIM(B71)="Front End Loader",TRIM(B71)="Fel"),"Front End Loader",IF(OR(TRIM(B71)="Surface Miner",TRIM(B71)="Csm"),"Surface Miner",IF(TRIM(B71)="Diesel Bowser","Diesel Bowser","Other")))))) -> Dumper | AD71: =IF(E71=0,"Non-Operational","Operational") -> Operational | AE71: =IF(OR(C71=54,C71=67,C71=10,C71=16,C71=6,C71=12,C71=28),"Aggregate","Individual") -> Individual
A72: 2 | B72: Dumper | C72: S-035 | D72: 720.0007 | E72: 225.2231 | F72: 192.8653 | G72: 189.1024 | H72: 494.7776 | I72: 11.1626 | J72: 32.3578 | K72: 9.8414 | L72: 189.1024 | M72: 21.004 | N72: 210.1064 | O72: 0.31280956 | P72: 0.83962258 | Q72: 0 | R72: 0 | S72: 0 | T72: 387 | U72: =T72*V72 -> 9675 | V72: 25 | W72: 2711.14 | X72: 12.903653 | Y72: 2440.1117 | Z72: 271.02832 | AA72: 0 | AB72: 0 | AC72: =IF(OR(TRIM(B72)="Tipper",TRIM(B72)="Volvo",TRIM(B72)="Bharatbenz"),"Tipper",IF(OR(TRIM(B72)="Dumper",TRIM(B72)="Sany",TRIM(B72)="Komatsu"),"Dumper",IF(TRIM(B72)="Excavator","Excavator",IF(OR(TRIM(B72)="Front End Loader",TRIM(B72)="Fel"),"Front End Loader",IF(OR(TRIM(B72)="Surface Miner",TRIM(B72)="Csm"),"Surface Miner",IF(TRIM(B72)="Diesel Bowser","Diesel Bowser","Other")))))) -> Dumper | AD72: =IF(E72=0,"Non-Operational","Operational") -> Operational | AE72: =IF(OR(C72=54,C72=67,C72=10,C72=16,C72=6,C72=12,C72=28),"Aggregate","Individual") -> Individual
A73: 3 | B73: Dumper | C73: S-036 | D73: 720.0002 | E73: 409.1055 | F73: 348.534 | G73: 347.3511 | H73: 310.8947 | I73: 54.3023 | J73: 60.5715 | K73: 203.6836 | L73: 347.3511 | M73: 257.9859 | N73: 605.337 | O73: 0.56820193 | P73: 0.84905018 | Q73: 0 | R73: 0 | S73: 0 | T73: 566 | U73: =T73*V73 -> 14150 | V73: 25 | W73: 5375.5 | X73: 8.8801775 | Y73: 3084.5394 | Z73: 2290.9606 | AA73: 0 | AB73: 0 | AC73: =IF(OR(TRIM(B73)="Tipper",TRIM(B73)="Volvo",TRIM(B73)="Bharatbenz"),"Tipper",IF(OR(TRIM(B73)="Dumper",TRIM(B73)="Sany",TRIM(B73)="Komatsu"),"Dumper",IF(TRIM(B73)="Excavator","Excavator",IF(OR(TRIM(B73)="Front End Loader",TRIM(B73)="Fel"),"Front End Loader",IF(OR(TRIM(B73)="Surface Miner",TRIM(B73)="Csm"),"Surface Miner",IF(TRIM(B73)="Diesel Bowser","Diesel Bowser","Other")))))) -> Dumper | AD73: =IF(E73=0,"Non-Operational","Operational") -> Operational | AE73: =IF(OR(C73=54,C73=67,C73=10,C73=16,C73=6,C73=12,C73=28),"Aggregate","Individual") -> Individual
A74: 4 | B74: Dumper | C74: S-037 | D74: 719.9997 | E74: 441.6529 | F74: 373.9102 | G74: 368.4412 | H74: 278.3468 | I74: 29.2161 | J74: 67.7427 | K74: 16.2026 | L74: 368.4412 | M74: 45.4187 | N74: 413.8599 | O74: 0.61340706 | P74: 0.83423249 | Q74: 0 | R74: 0 | S74: 0 | T74: 633 | U74: =T74*V74 -> 15825 | V74: 25 | W74: 5889.54 | X74: 14.230758 | Y74: 5243.1975 | Z74: 646.34252 | AA74: 0 | AB74: 0 | AC74: =IF(OR(TRIM(B74)="Tipper",TRIM(B74)="Volvo",TRIM(B74)="Bharatbenz"),"Tipper",IF(OR(TRIM(B74)="Dumper",TRIM(B74)="Sany",TRIM(B74)="Komatsu"),"Dumper",IF(TRIM(B74)="Excavator","Excavator",IF(OR(TRIM(B74)="Front End Loader",TRIM(B74)="Fel"),"Front End Loader",IF(OR(TRIM(B74)="Surface Miner",TRIM(B74)="Csm"),"Surface Miner",IF(TRIM(B74)="Diesel Bowser","Diesel Bowser","Other")))))) -> Dumper | AD74: =IF(E74=0,"Non-Operational","Operational") -> Operational | AE74: =IF(OR(C74=54,C74=67,C74=10,C74=16,C74=6,C74=12,C74=28),"Aggregate","Individual") -> Individual
A75: 5 | B75: Dumper | C75: S-038 | D75: 720.0001 | E75: 361.4464 | F75: 313.6948 | G75: 310.49 | H75: 358.5537 | I75: 25.5788 | J75: 47.7516 | K75: 40.745 | L75: 310.49 | M75: 66.3238 | N75: 376.8138 | O75: 0.50200882 | P75: 0.85902087 | Q75: 0 | R75: 0 | S75: 0 | T75: 586 | U75: =T75*V75 -> 14650 | V75: 25 | W75: 4994.21 | X75: 13.253787 | Y75: 4115.1685 | Z75: 879.04155 | AA75: 0 | AB75: 0 | AC75: =IF(OR(TRIM(B75)="Tipper",TRIM(B75)="Volvo",TRIM(B75)="Bharatbenz"),"Tipper",IF(OR(TRIM(B75)="Dumper",TRIM(B75)="Sany",TRIM(B75)="Komatsu"),"Dumper",IF(TRIM(B75)="Excavator","Excavator",IF(OR(TRIM(B75)="Front End Loader",TRIM(B75)="Fel"),"Front End Loader",IF(OR(TRIM(B75)="Surface Miner",TRIM(B75)="Csm"),"Surface Miner",IF(TRIM(B75)="Diesel Bowser","Diesel Bowser","Other")))))) -> Dumper | AD75: =IF(E75=0,"Non-Operational","Operational") -> Operational | AE75: =IF(OR(C75=54,C75=67,C75=10,C75=16,C75=6,C75=12,C75=28),"Aggregate","Individual") -> Individual
A76: 6 | B76: Dumper | C76: S-039 | D76: 719.9997 | E76: 427.2625 | F76: 368.9284 | G76: 366.4175 | H76: 292.7372 | I76: 43.6117 | J76: 58.3341 | K76: 27.2088 | L76: 366.4175 | M76: 70.8205 | N76: 437.238 | O76: 0.59342039 | P76: 0.8575934 | Q76: 13 | R76: 529.7 | S76: 40.746154 | T76: 685 | U76: =T76*V76 -> 17125 | V76: 25 | W76: 5923.09 | X76: 13.546604 | Y76: 4963.7127 | Z76: 959.37726 | AA76: 8.4858023 | AB76: 0.62779845 | AC76: =IF(OR(TRIM(B76)="Tipper",TRIM(B76)="Volvo",TRIM(B76)="Bharatbenz"),"Tipper",IF(OR(TRIM(B76)="Dumper",TRIM(B76)="Sany",TRIM(B76)="Komatsu"),"Dumper",IF(TRIM(B76)="Excavator","Excavator",IF(OR(TRIM(B76)="Front End Loader",TRIM(B76)="Fel"),"Front End Loader",IF(OR(TRIM(B76)="Surface Miner",TRIM(B76)="Csm"),"Surface Miner",IF(TRIM(B76)="Diesel Bowser","Diesel Bowser","Other")))))) -> Dumper | AD76: =IF(E76=0,"Non-Operational","Operational") -> Operational | AE76: =IF(OR(C76=54,C76=67,C76=10,C76=16,C76=6,C76=12,C76=28),"Aggregate","Individual") -> Individual
A77: 7 | B77: Dumper | C77: S-041 | D77: 720.0001 | E77: 248.2374 | F77: 214.7977 | G77: 210.4824 | H77: 471.7627 | I77: 8.5946 | J77: 33.4397 | K77: 2.4945 | L77: 210.4824 | M77: 11.0891 | N77: 221.5715 | O77: 0.34477412 | P77: 0.84790769 | Q77: 0 | R77: 0 | S77: 0 | T77: 745 | U77: =T77*V77 -> 18625 | V77: 25 | W77: 6712.86 | X77: 30.296586 | Y77: 6376.8981 | Z77: 335.96187 | AA77: 0 | AB77: 0 | AC77: =IF(OR(TRIM(B77)="Tipper",TRIM(B77)="Volvo",TRIM(B77)="Bharatbenz"),"Tipper",IF(OR(TRIM(B77)="Dumper",TRIM(B77)="Sany",TRIM(B77)="Komatsu"),"Dumper",IF(TRIM(B77)="Excavator","Excavator",IF(OR(TRIM(B77)="Front End Loader",TRIM(B77)="Fel"),"Front End Loader",IF(OR(TRIM(B77)="Surface Miner",TRIM(B77)="Csm"),"Surface Miner",IF(TRIM(B77)="Diesel Bowser","Diesel Bowser","Other")))))) -> Dumper | AD77: =IF(E77=0,"Non-Operational","Operational") -> Operational | AE77: =IF(OR(C77=54,C77=67,C77=10,C77=16,C77=6,C77=12,C77=28),"Aggregate","Individual") -> Individual
A78: 8 | B78: Dumper | C78: S-042 | D78: 719.9988 | E78: 496.0294 | F78: 433.7134 | G78: 427.5354 | H78: 223.9694 | I78: 23.2179 | J78: 62.316 | K78: 14.1645 | L78: 427.5354 | M78: 37.3824 | N78: 464.9178 | O78: 0.68893087 | P78: 0.86191544 | Q78: 0 | R78: 0 | S78: 0 | T78: 865 | U78: =T78*V78 -> 21625 | V78: 25 | W78: 6827.27 | X78: 14.684897 | Y78: 6278.3133 | Z78: 548.95669 | AA78: 0 | AB78: 0 | AC78: =IF(OR(TRIM(B78)="Tipper",TRIM(B78)="Volvo",TRIM(B78)="Bharatbenz"),"Tipper",IF(OR(TRIM(B78)="Dumper",TRIM(B78)="Sany",TRIM(B78)="Komatsu"),"Dumper",IF(TRIM(B78)="Excavator","Excavator",IF(OR(TRIM(B78)="Front End Loader",TRIM(B78)="Fel"),"Front End Loader",IF(OR(TRIM(B78)="Surface Miner",TRIM(B78)="Csm"),"Surface Miner",IF(TRIM(B78)="Diesel Bowser","Diesel Bowser","Other")))))) -> Dumper | AD78: =IF(E78=0,"Non-Operational","Operational") -> Operational | AE78: =IF(OR(C78=54,C78=67,C78=10,C78=16,C78=6,C78=12,C78=28),"Aggregate","Individual") -> Individual
A79: 9 | B79: Dumper | C79: S-043 | D79: 719.9999 | E79: 578.2461 | F79: 512.4886 | G79: 502.4779 | H79: 141.7538 | I79: 27.6905 | J79: 65.7575 | K79: 4.8203 | L79: 502.4779 | M79: 32.5108 | N79: 534.9887 | O79: 0.80311969 | P79: 0.86896894 | Q79: 0 | R79: 0 | S79: 0 | T79: 1001 | U79: =T79*V79 -> 25025 | V79: 25 | W79: 7625.29 | X79: 14.25318 | Y79: 7161.9077 | Z79: 463.38227 | AA79: 0 | AB79: 0 | AC79: =IF(OR(TRIM(B79)="Tipper",TRIM(B79)="Volvo",TRIM(B79)="Bharatbenz"),"Tipper",IF(OR(TRIM(B79)="Dumper",TRIM(B79)="Sany",TRIM(B79)="Komatsu"),"Dumper",IF(TRIM(B79)="Excavator","Excavator",IF(OR(TRIM(B79)="Front End Loader",TRIM(B79)="Fel"),"Front End Loader",IF(OR(TRIM(B79)="Surface Miner",TRIM(B79)="Csm"),"Surface Miner",IF(TRIM(B79)="Diesel Bowser","Diesel Bowser","Other")))))) -> Dumper | AD79: =IF(E79=0,"Non-Operational","Operational") -> Operational | AE79: =IF(OR(C79=54,C79=67,C79=10,C79=16,C79=6,C79=12,C79=28),"Aggregate","Individual") -> Individual
A80: 10 | B80: Dumper | C80: S-045 | D80: 719.9995 | E80: 420.6018 | F80: 354.308 | G80: 350.4056 | H80: 299.3977 | I80: 46.9235 | J80: 66.2938 | K80: 46.65 | L80: 350.4056 | M80: 93.5735 | N80: 443.9791 | O80: 0.58416957 | P80: 0.83310533 | Q80: 0 | R80: 0 | S80: 0 | T80: 608 | U80: =T80*V80 -> 15200 | V80: 25 | W80: 5500.76 | X80: 12.389682 | Y80: 4341.4141 | Z80: 1159.3459 | AA80: 0 | AB80: 0 | AC80: =IF(OR(TRIM(B80)="Tipper",TRIM(B80)="Volvo",TRIM(B80)="Bharatbenz"),"Tipper",IF(OR(TRIM(B80)="Dumper",TRIM(B80)="Sany",TRIM(B80)="Komatsu"),"Dumper",IF(TRIM(B80)="Excavator","Excavator",IF(OR(TRIM(B80)="Front End Loader",TRIM(B80)="Fel"),"Front End Loader",IF(OR(TRIM(B80)="Surface Miner",TRIM(B80)="Csm"),"Surface Miner",IF(TRIM(B80)="Diesel Bowser","Diesel Bowser","Other")))))) -> Dumper | AD80: =IF(E80=0,"Non-Operational","Operational") -> Operational | AE80: =IF(OR(C80=54,C80=67,C80=10,C80=16,C80=6,C80=12,C80=28),"Aggregate","Individual") -> Individual
A81: 11 | B81: Dumper | C81: S-046 | D81: 719.9999 | E81: 4.5402 | F81: 3.3616 | G81: 3.2211 | H81: 715.4597 | I81: 0.0513 | J81: 1.1786 | K81: 0.0403 | L81: 3.2211 | M81: 0.0916 | N81: 3.3127 | O81: 0.0063058342 | P81: 0.70946214 | Q81: 0 | R81: 0 | S81: 0 | T81: 14 | U81: =T81*V81 -> 350 | V81: 25 | W81: 223.66 | X81: 67.515924 | Y81: 217.47554 | Z81: 6.1844586 | AA81: 0 | AB81: 0 | AC81: =IF(OR(TRIM(B81)="Tipper",TRIM(B81)="Volvo",TRIM(B81)="Bharatbenz"),"Tipper",IF(OR(TRIM(B81)="Dumper",TRIM(B81)="Sany",TRIM(B81)="Komatsu"),"Dumper",IF(TRIM(B81)="Excavator","Excavator",IF(OR(TRIM(B81)="Front End Loader",TRIM(B81)="Fel"),"Front End Loader",IF(OR(TRIM(B81)="Surface Miner",TRIM(B81)="Csm"),"Surface Miner",IF(TRIM(B81)="Diesel Bowser","Diesel Bowser","Other")))))) -> Dumper | AD81: =IF(E81=0,"Non-Operational","Operational") -> Operational | AE81: =IF(OR(C81=54,C81=67,C81=10,C81=16,C81=6,C81=12,C81=28),"Aggregate","Individual") -> Individual
...

Sheet Executive Summary
A1: TALABIRA MINE – FMS PERFORMANCE ANALYSIS | APRIL 2025
A2: Adani Natural Resources | Fleet Management System (FMS) Data
A4: FLEET PERFORMANCE SNAPSHOT – APRIL 2025 (All values = Raw Data formulas)
A5: Equipment Group | B5: Total Units | C5: Operational | D5: Non-Op | E5: Avg Avail % | F5: Avg Util % | G5: Total Diesel (L) | H5: OB CUM (m³) | I5: ROM (Tonnes) | J5: Avg Idle Hrs/Unit | K5: Avg Brkdn Hrs/Unit
A6: Tipper | B6: =COUNTIFS('Raw Data'!AC:AC,$A6,'Raw Data'!AE:AE,"Individual") -> 66 | C6: =COUNTIFS('Raw Data'!AC:AC,$A6,'Raw Data'!AD:AD,"Operational",'Raw Data'!AE:AE,"Individual") -> 62 | D6: =B6-C6 -> 4 | E6: =IFERROR(AVERAGEIFS('Raw Data'!O:O,'Raw Data'!AC:AC,$A6,'Raw Data'!AD:AD,"Operational",'Raw Data'!AE:AE,"Individual"),0) -> 0.6335626 | F6: =IFERROR(AVERAGEIFS('Raw Data'!P:P,'Raw Data'!AC:AC,$A6,'Raw Data'!AD:AD,"Operational",'Raw Data'!AE:AE,"Individual"),0) -> 0.45551442 | G6: =SUMIFS('Raw Data'!W:W,'Raw Data'!AC:AC,$A6,'Raw Data'!AE:AE,"Individual") -> 189994.42 | H6: =SUMIFS('Raw Data'!U:U,'Raw Data'!AC:AC,$A6,'Raw Data'!AE:AE,"Individual") -> 11635 | I6: =SUMIFS('Raw Data'!R:R,'Raw Data'!AC:AC,$A6,'Raw Data'!AE:AE,"Individual") -> 1007304.3 | J6: =IFERROR(AVERAGEIFS('Raw Data'!J:J,'Raw Data'!AC:AC,$A6,'Raw Data'!AE:AE,"Individual"),0) -> 218.9115 | K6: =IFERROR(AVERAGEIFS('Raw Data'!H:H,'Raw Data'!AC:AC,$A6,'Raw Data'!AE:AE,"Individual"),0) -> 291.31556
A7: Dumper | B7: =COUNTIFS('Raw Data'!AC:AC,$A7,'Raw Data'!AE:AE,"Individual") -> 77 | C7: =COUNTIFS('Raw Data'!AC:AC,$A7,'Raw Data'!AD:AD,"Operational",'Raw Data'!AE:AE,"Individual") -> 75 | D7: =B7-C7 -> 2 | E7: =IFERROR(AVERAGEIFS('Raw Data'!O:O,'Raw Data'!AC:AC,$A7,'Raw Data'!AD:AD,"Operational",'Raw Data'!AE:AE,"Individual"),0) -> 0.60892491 | F7: =IFERROR(AVERAGEIFS('Raw Data'!P:P,'Raw Data'!AC:AC,$A7,'Raw Data'!AD:AD,"Operational",'Raw Data'!AE:AE,"Individual"),0) -> 0.81832106 | G7: =SUMIFS('Raw Data'!W:W,'Raw Data'!AC:AC,$A7,'Raw Data'!AE:AE,"Individual") -> 561685.83 | H7: =SUMIFS('Raw Data'!U:U,'Raw Data'!AC:AC,$A7,'Raw Data'!AE:AE,"Individual") -> 1469194 | I7: =SUMIFS('Raw Data'!R:R,'Raw Data'!AC:AC,$A7,'Raw Data'!AE:AE,"Individual") -> 1935.3 | J7: =IFERROR(AVERAGEIFS('Raw Data'!J:J,'Raw Data'!AC:AC,$A7,'Raw Data'!AE:AE,"Individual"),0) -> 65.605114 | K7: =IFERROR(AVERAGEIFS('Raw Data'!H:H,'Raw Data'!AC:AC,$A7,'Raw Data'!AE:AE,"Individual"),0) -> 292.92408
A8: Excavator | B8: =COUNTIFS('Raw Data'!AC:AC,$A8,'Raw Data'!AE:AE,"Individual") -> 28 | C8: =COUNTIFS('Raw Data'!AC:AC,$A8,'Raw Data'!AD:AD,"Operational",'Raw Data'!AE:AE,"Individual") -> 27 | D8: =B8-C8 -> 1 | E8: =IFERROR(AVERAGEIFS('Raw Data'!O:O,'Raw Data'!AC:AC,$A8,'Raw Data'!AD:AD,"Operational",'Raw Data'!AE:AE,"Individual"),0) -> 0.57197432 | F8: =IFERROR(AVERAGEIFS('Raw Data'!P:P,'Raw Data'!AC:AC,$A8,'Raw Data'!AD:AD,"Operational",'Raw Data'!AE:AE,"Individual"),0) -> 0.82977058 | G8: =SUMIFS('Raw Data'!W:W,'Raw Data'!AC:AC,$A8,'Raw Data'!AE:AE,"Individual") -> 526974 | H8: =SUMIFS('Raw Data'!U:U,'Raw Data'!AC:AC,$A8,'Raw Data'!AE:AE,"Individual") -> 0 | I8: =SUMIFS('Raw Data'!R:R,'Raw Data'!AC:AC,$A8,'Raw Data'!AE:AE,"Individual") -> 0 | J8: =IFERROR(AVERAGEIFS('Raw Data'!J:J,'Raw Data'!AC:AC,$A8,'Raw Data'!AE:AE,"Individual"),0) -> 48.545346 | K8: =IFERROR(AVERAGEIFS('Raw Data'!H:H,'Raw Data'!AC:AC,$A8,'Raw Data'!AE:AE,"Individual"),0) -> 322.4354
A9: Front End Loader | B9: =COUNTIFS('Raw Data'!AC:AC,$A9,'Raw Data'!AE:AE,"Individual") -> 16 | C9: =COUNTIFS('Raw Data'!AC:AC,$A9,'Raw Data'!AD:AD,"Operational",'Raw Data'!AE:AE,"Individual") -> 15 | D9: =B9-C9 -> 1 | E9: =IFERROR(AVERAGEIFS('Raw Data'!O:O,'Raw Data'!AC:AC,$A9,'Raw Data'!AD:AD,"Operational",'Raw Data'!AE:AE,"Individual"),0) -> 0.69993885 | F9: =IFERROR(AVERAGEIFS('Raw Data'!P:P,'Raw Data'!AC:AC,$A9,'Raw Data'!AD:AD,"Operational",'Raw Data'!AE:AE,"Individual"),0) -> 0.49329136 | G9: =SUMIFS('Raw Data'!W:W,'Raw Data'!AC:AC,$A9,'Raw Data'!AE:AE,"Individual") -> 104808.78 | H9: =SUMIFS('Raw Data'!U:U,'Raw Data'!AC:AC,$A9,'Raw Data'!AE:AE,"Individual") -> 0 | I9: =SUMIFS('Raw Data'!R:R,'Raw Data'!AC:AC,$A9,'Raw Data'!AE:AE,"Individual") -> 0 | J9: =IFERROR(AVERAGEIFS('Raw Data'!J:J,'Raw Data'!AC:AC,$A9,'Raw Data'!AE:AE,"Individual"),0) -> 238.82705 | K9: =IFERROR(AVERAGEIFS('Raw Data'!H:H,'Raw Data'!AC:AC,$A9,'Raw Data'!AE:AE,"Individual"),0) -> 246.83226
A10: Surface Miner | B10: =COUNTIFS('Raw Data'!AC:AC,$A10,'Raw Data'!AE:AE,"Individual") -> 6 | C10: =COUNTIFS('Raw Data'!AC:AC,$A10,'Raw Data'!AD:AD,"Operational",'Raw Data'!AE:AE,"Individual") -> 5 | D10: =B10-C10 -> 1 | E10: =IFERROR(AVERAGEIFS('Raw Data'!O:O,'Raw Data'!AC:AC,$A10,'Raw Data'!AD:AD,"Operational",'Raw Data'!AE:AE,"Individual"),0) -> 0.52831484 | F10: =IFERROR(AVERAGEIFS('Raw Data'!P:P,'Raw Data'!AC:AC,$A10,'Raw Data'!AD:AD,"Operational",'Raw Data'!AE:AE,"Individual"),0) -> 0.88939929 | G10: =SUMIFS('Raw Data'!W:W,'Raw Data'!AC:AC,$A10,'Raw Data'!AE:AE,"Individual") -> 131057.1 | H10: =SUMIFS('Raw Data'!U:U,'Raw Data'!AC:AC,$A10,'Raw Data'!AE:AE,"Individual") -> 0 | I10: =SUMIFS('Raw Data'!R:R,'Raw Data'!AC:AC,$A10,'Raw Data'!AE:AE,"Individual") -> 0 | J10: =IFERROR(AVERAGEIFS('Raw Data'!J:J,'Raw Data'!AC:AC,$A10,'Raw Data'!AE:AE,"Individual"),0) -> 25.5958 | K10: =IFERROR(AVERAGEIFS('Raw Data'!H:H,'Raw Data'!AC:AC,$A10,'Raw Data'!AE:AE,"Individual"),0) -> 400.21868
A11: Diesel Bowser | B11: =COUNTIFS('Raw Data'!AC:AC,$A11,'Raw Data'!AE:AE,"Individual") -> 6 | C11: =COUNTIFS('Raw Data'!AC:AC,$A11,'Raw Data'!AD:AD,"Operational",'Raw Data'!AE:AE,"Individual") -> 6 | D11: =B11-C11 -> 0 | E11: =IFERROR(AVERAGEIFS('Raw Data'!O:O,'Raw Data'!AC:AC,$A11,'Raw Data'!AD:AD,"Operational",'Raw Data'!AE:AE,"Individual"),0) -> 0.67771641 | F11: =IFERROR(AVERAGEIFS('Raw Data'!P:P,'Raw Data'!AC:AC,$A11,'Raw Data'!AD:AD,"Operational",'Raw Data'!AE:AE,"Individual"),0) -> 0.16805613 | G11: =SUMIFS('Raw Data'!W:W,'Raw Data'!AC:AC,$A11,'Raw Data'!AE:AE,"Individual") -> 4386.17 | H11: =SUMIFS('Raw Data'!U:U,'Raw Data'!AC:AC,$A11,'Raw Data'!AE:AE,"Individual") -> 0 | I11: =SUMIFS('Raw Data'!R:R,'Raw Data'!AC:AC,$A11,'Raw Data'!AE:AE,"Individual") -> 0 | J11: =IFERROR(AVERAGEIFS('Raw Data'!J:J,'Raw Data'!AC:AC,$A11,'Raw Data'!AE:AE,"Individual"),0) -> 291.48468 | K11: =IFERROR(AVERAGEIFS('Raw Data'!H:H,'Raw Data'!AC:AC,$A11,'Raw Data'!AE:AE,"Individual"),0) -> 232.04447
A13: KEY PERFORMANCE INDICATORS
A14: Total Fleet | C14: Operational | E14: Fleet Avail % | G14: Fleet Util % | I14: Total Diesel (L)
A15: =COUNTIFS('Raw Data'!AE:AE,"Individual") -> 199 | C15: =COUNTIFS('Raw Data'!AD:AD,"Operational",'Raw Data'!AE:AE,"Individual") -> 190 | E15: =IFERROR(AVERAGEIFS('Raw Data'!O:O,'Raw Data'!AD:AD,"Operational",'Raw Data'!AE:AE,"Individual"),0) -> 0.61895006 | G15: =IFERROR(AVERAGEIFS('Raw Data'!P:P,'Raw Data'!AD:AD,"Operational",'Raw Data'!AE:AE,"Individual"),0) -> 0.65723412 | I15: =SUMIFS('Raw Data'!W:W,'Raw Data'!AE:AE,"Individual") -> 1518906.3
A17: Total OB CUM | C17: Total ROM (T) | E17: Total Idle Hrs | G17: Non-Op Units | I17: Total Brkdn Hrs
A18: =SUMIFS('Raw Data'!U:U,'Raw Data'!AE:AE,"Individual") -> 1480829 | C18: =SUMIFS('Raw Data'!R:R,'Raw Data'!AE:AE,"Individual") -> 1009239.6 | E18: =SUMIFS('Raw Data'!J:J,'Raw Data'!AE:AE,"Individual") -> 26582.738 | G18: =COUNTIFS('Raw Data'!AD:AD,"Non-Operational",'Raw Data'!AE:AE,"Individual") -> 9 | I18: =SUMIFS('Raw Data'!H:H,'Raw Data'!AE:AE,"Individual") -> 58553.067
A23: DATA NOTES
A24: • All values = SUMIFS/AVERAGEIFS/COUNTIFS formulas linked to Raw Data sheet.
A25: • Helper columns AC (Equip Group), AD (Status), AE (Row Type) in Raw Data power all lookups.
A26: • April 2025: 720 shift hrs (30 days). Normalise per-day when comparing months.

Sheet Avail & Utilization
A1: AVAILABILITY & UTILIZATION | APRIL 2025 — Values from Raw Data formulas
A3: Equipment ID pre-populated | All other columns = INDEX/MATCH from Raw Data
A4: Equip Group | B4: Equipment ID | C4: Shift Hrs | D4: Avail Hrs | E4: Breakdown Hrs | F4: Idle Hrs | G4: Availability % | H4: Utilization % | I4: Status
A5: Dumper
A6: =IFERROR(INDEX('Raw Data'!AC:AC,MATCH($B6,'Raw Data'!$C:$C,0)),"") -> Dumper | B6: S-382 | C6: =IFERROR(INDEX('Raw Data'!D:D,MATCH($B6,'Raw Data'!$C:$C,0)),"-") -> 720.0002 | D6: =IFERROR(INDEX('Raw Data'!E:E,MATCH($B6,'Raw Data'!$C:$C,0)),"-") -> 660.5691 | E6: =IFERROR(INDEX('Raw Data'!H:H,MATCH($B6,'Raw Data'!$C:$C,0)),"-") -> 59.4311 | F6: =IFERROR(INDEX('Raw Data'!J:J,MATCH($B6,'Raw Data'!$C:$C,0)),"-") -> 76.0676 | G6: =IFERROR(INDEX('Raw Data'!O:O,MATCH($B6,'Raw Data'!$C:$C,0)),"-") -> 0.91745683 | H6: =IFERROR(INDEX('Raw Data'!P:P,MATCH($B6,'Raw Data'!$C:$C,0)),"-") -> 0.86978062 | I6: =IFERROR(INDEX('Raw Data'!AD:AD,MATCH($B6,'Raw Data'!$C:$C,0)),"-") -> Operational
A7: =IFERROR(INDEX('Raw Data'!AC:AC,MATCH($B7,'Raw Data'!$C:$C,0)),"") -> Dumper | B7: S-371 | C7: =IFERROR(INDEX('Raw Data'!D:D,MATCH($B7,'Raw Data'!$C:$C,0)),"-") -> 720.0002 | D7: =IFERROR(INDEX('Raw Data'!E:E,MATCH($B7,'Raw Data'!$C:$C,0)),"-") -> 656.9704 | E7: =IFERROR(INDEX('Raw Data'!H:H,MATCH($B7,'Raw Data'!$C:$C,0)),"-") -> 63.0298 | F7: =IFERROR(INDEX('Raw Data'!J:J,MATCH($B7,'Raw Data'!$C:$C,0)),"-") -> 77.2461 | G7: =IFERROR(INDEX('Raw Data'!O:O,MATCH($B7,'Raw Data'!$C:$C,0)),"-") -> 0.91245864 | H7: =IFERROR(INDEX('Raw Data'!P:P,MATCH($B7,'Raw Data'!$C:$C,0)),"-") -> 0.86720985 | I7: =IFERROR(INDEX('Raw Data'!AD:AD,MATCH($B7,'Raw Data'!$C:$C,0)),"-") -> Operational
A8: =IFERROR(INDEX('Raw Data'!AC:AC,MATCH($B8,'Raw Data'!$C:$C,0)),"") -> Dumper | B8: K-004 | C8: =IFERROR(INDEX('Raw Data'!D:D,MATCH($B8,'Raw Data'!$C:$C,0)),"-") -> 720.0003 | D8: =IFERROR(INDEX('Raw Data'!E:E,MATCH($B8,'Raw Data'!$C:$C,0)),"-") -> 654.6692 | E8: =IFERROR(INDEX('Raw Data'!H:H,MATCH($B8,'Raw Data'!$C:$C,0)),"-") -> 65.3311 | F8: =IFERROR(INDEX('Raw Data'!J:J,MATCH($B8,'Raw Data'!$C:$C,0)),"-") -> 572.9036 | G8: =IFERROR(INDEX('Raw Data'!O:O,MATCH($B8,'Raw Data'!$C:$C,0)),"-") -> 0.9092624 | H8: =IFERROR(INDEX('Raw Data'!P:P,MATCH($B8,'Raw Data'!$C:$C,0)),"-") -> 0.12428155 | I8: =IFERROR(INDEX('Raw Data'!AD:AD,MATCH($B8,'Raw Data'!$C:$C,0)),"-") -> Operational
A9: =IFERROR(INDEX('Raw Data'!AC:AC,MATCH($B9,'Raw Data'!$C:$C,0)),"") -> Dumper | B9: S-386 | C9: =IFERROR(INDEX('Raw Data'!D:D,MATCH($B9,'Raw Data'!$C:$C,0)),"-") -> 719.9992 | D9: =IFERROR(INDEX('Raw Data'!E:E,MATCH($B9,'Raw Data'!$C:$C,0)),"-") -> 651.4783 | E9: =IFERROR(INDEX('Raw Data'!H:H,MATCH($B9,'Raw Data'!$C:$C,0)),"-") -> 68.5209 | F9: =IFERROR(INDEX('Raw Data'!J:J,MATCH($B9,'Raw Data'!$C:$C,0)),"-") -> 76.2798 | G9: =IFERROR(INDEX('Raw Data'!O:O,MATCH($B9,'Raw Data'!$C:$C,0)),"-") -> 0.90483198 | H9: =IFERROR(INDEX('Raw Data'!P:P,MATCH($B9,'Raw Data'!$C:$C,0)),"-") -> 0.86610498 | I9: =IFERROR(INDEX('Raw Data'!AD:AD,MATCH($B9,'Raw Data'!$C:$C,0)),"-") -> Operational
A10: =IFERROR(INDEX('Raw Data'!AC:AC,MATCH($B10,'Raw Data'!$C:$C,0)),"") -> Dumper | B10: S-405 | C10: =IFERROR(INDEX('Raw Data'!D:D,MATCH($B10,'Raw Data'!$C:$C,0)),"-") -> 720.0012 | D10: =IFERROR(INDEX('Raw Data'!E:E,MATCH($B10,'Raw Data'!$C:$C,0)),"-") -> 650.2439 | E10: =IFERROR(INDEX('Raw Data'!H:H,MATCH($B10,'Raw Data'!$C:$C,0)),"-") -> 69.7573 | F10: =IFERROR(INDEX('Raw Data'!J:J,MATCH($B10,'Raw Data'!$C:$C,0)),"-") -> 359.0569 | G10: =IFERROR(INDEX('Raw Data'!O:O,MATCH($B10,'Raw Data'!$C:$C,0)),"-") -> 0.90311502 | H10: =IFERROR(INDEX('Raw Data'!P:P,MATCH($B10,'Raw Data'!$C:$C,0)),"-") -> 0.44415872 | I10: =IFERROR(INDEX('Raw Data'!AD:AD,MATCH($B10,'Raw Data'!$C:$C,0)),"-") -> Operational
A11: =IFERROR(INDEX('Raw Data'!AC:AC,MATCH($B11,'Raw Data'!$C:$C,0)),"") -> Dumper | B11: S-256 | C11: =IFERROR(INDEX('Raw Data'!D:D,MATCH($B11,'Raw Data'!$C:$C,0)),"-") -> 720.0007 | D11: =IFERROR(INDEX('Raw Data'!E:E,MATCH($B11,'Raw Data'!$C:$C,0)),"-") -> 638.3469 | E11: =IFERROR(INDEX('Raw Data'!H:H,MATCH($B11,'Raw Data'!$C:$C,0)),"-") -> 81.6538 | F11: =IFERROR(INDEX('Raw Data'!J:J,MATCH($B11,'Raw Data'!$C:$C,0)),"-") -> 76.5306 | G11: =IFERROR(INDEX('Raw Data'!O:O,MATCH($B11,'Raw Data'!$C:$C,0)),"-") -> 0.88659205 | H11: =IFERROR(INDEX('Raw Data'!P:P,MATCH($B11,'Raw Data'!$C:$C,0)),"-") -> 0.86366754 | I11: =IFERROR(INDEX('Raw Data'!AD:AD,MATCH($B11,'Raw Data'!$C:$C,0)),"-") -> Operational
A12: =IFERROR(INDEX('Raw Data'!AC:AC,MATCH($B12,'Raw Data'!$C:$C,0)),"") -> Dumper | B12: K-002 | C12: =IFERROR(INDEX('Raw Data'!D:D,MATCH($B12,'Raw Data'!$C:$C,0)),"-") -> 720.0002 | D12: =IFERROR(INDEX('Raw Data'!E:E,MATCH($B12,'Raw Data'!$C:$C,0)),"-") -> 635.912 | E12: =IFERROR(INDEX('Raw Data'!H:H,MATCH($B12,'Raw Data'!$C:$C,0)),"-") -> 84.0882 | F12: =IFERROR(INDEX('Raw Data'!J:J,MATCH($B12,'Raw Data'!$C:$C,0)),"-") -> 75.2487 | G12: =IFERROR(INDEX('Raw Data'!O:O,MATCH($B12,'Raw Data'!$C:$C,0)),"-") -> 0.88321087 | H12: =IFERROR(INDEX('Raw Data'!P:P,MATCH($B12,'Raw Data'!$C:$C,0)),"-") -> 0.8714525 | I12: =IFERROR(INDEX('Raw Data'!AD:AD,MATCH($B12,'Raw Data'!$C:$C,0)),"-") -> Operational
A13: =IFERROR(INDEX('Raw Data'!AC:AC,MATCH($B13,'Raw Data'!$C:$C,0)),"") -> Dumper | B13: S-258 | C13: =IFERROR(INDEX('Raw Data'!D:D,MATCH($B13,'Raw Data'!$C:$C,0)),"-") -> 720 | D13: =IFERROR(INDEX('Raw Data'!E:E,MATCH($B13,'Raw Data'!$C:$C,0)),"-") -> 630.8695 | E13: =IFERROR(INDEX('Raw Data'!H:H,MATCH($B13,'Raw Data'!$C:$C,0)),"-") -> 89.1305 | F13: =IFERROR(INDEX('Raw Data'!J:J,MATCH($B13,'Raw Data'!$C:$C,0)),"-") -> 73.2769 | G13: =IFERROR(INDEX('Raw Data'!O:O,MATCH($B13,'Raw Data'!$C:$C,0)),"-") -> 0.87620764 | H13: =IFERROR(INDEX('Raw Data'!P:P,MATCH($B13,'Raw Data'!$C:$C,0)),"-") -> 0.86799822 | I13: =IFERROR(INDEX('Raw Data'!AD:AD,MATCH($B13,'Raw Data'!$C:$C,0)),"-") -> Operational
A14: =IFERROR(INDEX('Raw Data'!AC:AC,MATCH($B14,'Raw Data'!$C:$C,0)),"") -> Dumper | B14: S-387 | C14: =IFERROR(INDEX('Raw Data'!D:D,MATCH($B14,'Raw Data'!$C:$C,0)),"-") -> 719.9991 | D14: =IFERROR(INDEX('Raw Data'!E:E,MATCH($B14,'Raw Data'!$C:$C,0)),"-") -> 628.7337 | E14: =IFERROR(INDEX('Raw Data'!H:H,MATCH($B14,'Raw Data'!$C:$C,0)),"-") -> 91.2654 | F14: =IFERROR(INDEX('Raw Data'!J:J,MATCH($B14,'Raw Data'!$C:$C,0)),"-") -> 77.3657 | G14: =IFERROR(INDEX('Raw Data'!O:O,MATCH($B14,'Raw Data'!$C:$C,0)),"-") -> 0.87324234 | H14: =IFERROR(INDEX('Raw Data'!P:P,MATCH($B14,'Raw Data'!$C:$C,0)),"-") -> 0.8568615 | I14: =IFERROR(INDEX('Raw Data'!AD:AD,MATCH($B14,'Raw Data'!$C:$C,0)),"-") -> Operational
A15: =IFERROR(INDEX('Raw Data'!AC:AC,MATCH($B15,'Raw Data'!$C:$C,0)),"") -> Dumper | B15: S-255 | C15: =IFERROR(INDEX('Raw Data'!D:D,MATCH($B15,'Raw Data'!$C:$C,0)),"-") -> 720 | D15: =IFERROR(INDEX('Raw Data'!E:E,MATCH($B15,'Raw Data'!$C:$C,0)),"-") -> 627.5058 | E15: =IFERROR(INDEX('Raw Data'!H:H,MATCH($B15,'Raw Data'!$C:$C,0)),"-") -> 92.4942 | F15: =IFERROR(INDEX('Raw Data'!J:J,MATCH($B15,'Raw Data'!$C:$C,0)),"-") -> 73.1541 | G15: =IFERROR(INDEX('Raw Data'!O:O,MATCH($B15,'Raw Data'!$C:$C,0)),"-") -> 0.87153583 | H15: =IFERROR(INDEX('Raw Data'!P:P,MATCH($B15,'Raw Data'!$C:$C,0)),"-") -> 0.87258237 | I15: =IFERROR(INDEX('Raw Data'!AD:AD,MATCH($B15,'Raw Data'!$C:$C,0)),"-") -> Operational
A16: =IFERROR(INDEX('Raw Data'!AC:AC,MATCH($B16,'Raw Data'!$C:$C,0)),"") -> Dumper | B16: S-251 | C16: =IFERROR(INDEX('Raw Data'!D:D,MATCH($B16,'Raw Data'!$C:$C,0)),"-") -> 720.0013 | D16: =IFERROR(INDEX('Raw Data'!E:E,MATCH($B16,'Raw Data'!$C:$C,0)),"-") -> 625.1047 | E16: =IFERROR(INDEX('Raw Data'!H:H,MATCH($B16,'Raw Data'!$C:$C,0)),"-") -> 94.8966 | F16: =IFERROR(INDEX('Raw Data'!J:J,MATCH($B16,'Raw Data'!$C:$C,0)),"-") -> 77.4485 | G16: =IFERROR(INDEX('Raw Data'!O:O,MATCH($B16,'Raw Data'!$C:$C,0)),"-") -> 0.8681994 | H16: =IFERROR(INDEX('Raw Data'!P:P,MATCH($B16,'Raw Data'!$C:$C,0)),"-") -> 0.8621039 | I16: =IFERROR(INDEX('Raw Data'!AD:AD,MATCH($B16,'Raw Data'!$C:$C,0)),"-") -> Operational
A17: =IFERROR(INDEX('Raw Data'!AC:AC,MATCH($B17,'Raw Data'!$C:$C,0)),"") -> Dumper | B17: S-250 | C17: =IFERROR(INDEX('Raw Data'!D:D,MATCH($B17,'Raw Data'!$C:$C,0)),"-") -> 720 | D17: =IFERROR(INDEX('Raw Data'!E:E,MATCH($B17,'Raw Data'!$C:$C,0)),"-") -> 623.4527 | E17: =IFERROR(INDEX('Raw Data'!H:H,MATCH($B17,'Raw Data'!$C:$C,0)),"-") -> 96.5473 | F17: =IFERROR(INDEX('Raw Data'!J:J,MATCH($B17,'Raw Data'!$C:$C,0)),"-") -> 126.0334 | G17: =IFERROR(INDEX('Raw Data'!O:O,MATCH($B17,'Raw Data'!$C:$C,0)),"-") -> 0.86590653 | H17: =IFERROR(INDEX('Raw Data'!P:P,MATCH($B17,'Raw Data'!$C:$C,0)),"-") -> 0.78502828 | I17: =IFERROR(INDEX('Raw Data'!AD:AD,MATCH($B17,'Raw Data'!$C:$C,0)),"-") -> Operational
... A82: =IFERROR(INDEX('Raw Data'!AC:AC,MATCH($B82,'Raw Data'!$C:$C,0)),"") -> Dumper | B82: S-373 | C82: =IFERROR(INDEX('Raw Data'!D:D,MATCH($B82,'Raw Data'!$C:$C,0)),"-") -> 720 | D82: =IFERROR(INDEX('Raw Data'!E:E,MATCH($B82,'Raw Data'!$C:$C,0)),"-") -> 0 | E82: =IFERROR(INDEX('Raw Data'!H:H,MATCH($B82,'Raw Data'!$C:$C,0)),"-") -> 720 | F82: =IFERROR(INDEX('Raw Data'!J:J,MATCH($B82,'Raw Data'!$C:$C,0)),"-") -> 0 | G82: =IFERROR(INDEX('Raw Data'!O:O,MATCH($B82,'Raw Data'!$C:$C,0)),"-") -> 0 | H82: =IFERROR(INDEX('Raw Data'!P:P,MATCH($B82,'Raw Data'!$C:$C,0)),"-") -> 0 | I82: =IFERROR(INDEX('Raw Data'!AD:AD,MATCH($B82,'Raw Data'!$C:$C,0)),"-") -> Non-Operational
A83: Excavator
A84: =IFERROR(INDEX('Raw Data'!AC:AC,MATCH($B84,'Raw Data'!$C:$C,0)),"") -> Excavator | B84: EX-001 | C84: =IFERROR(INDEX('Raw Data'!D:D,MATCH($B84,'Raw Data'!$C:$C,0)),"-") -> 719.9997 | D84: =IFERROR(INDEX('Raw Data'!E:E,MATCH($B84,'Raw Data'!$C:$C,0)),"-") -> 694.4921 | E84: =IFERROR(INDEX('Raw Data'!H:H,MATCH($B84,'Raw Data'!$C:$C,0)),"-") -> 25.5076 | F84: =IFERROR(INDEX('Raw Data'!J:J,MATCH($B84,'Raw Data'!$C:$C,0)),"-") -> 57.0951 | G84: =IFERROR(INDEX('Raw Data'!O:O,MATCH($B84,'Raw Data'!$C:$C,0)),"-") -> 0.96457276 | H84: =IFERROR(INDEX('Raw Data'!P:P,MATCH($B84,'Raw Data'!$C:$C,0)),"-") -> 0.88759915 | I84: =IFERROR(INDEX('Raw Data'!AD:AD,MATCH($B84,'Raw Data'!$C:$C,0)),"-") -> Operational
A85: =IFERROR(INDEX('Raw Data'!AC:AC,MATCH($B85,'Raw Data'!$C:$C,0)),"") -> Excavator | B85: EX-148 | C85: =IFERROR(INDEX('Raw Data'!D:D,MATCH($B85,'Raw Data'!$C:$C,0)),"-") -> 719.9995 | D85: =IFERROR(INDEX('Raw Data'!E:E,MATCH($B85,'Raw Data'!$C:$C,0)),"-") -> 685.2531 | E85: =IFERROR(INDEX('Raw Data'!H:H,MATCH($B85,'Raw Data'!$C:$C,0)),"-") -> 34.7464 | F85: =IFERROR(INDEX('Raw Data'!J:J,MATCH($B85,'Raw Data'!$C:$C,0)),"-") -> 75.0922 | G85: =IFERROR(INDEX('Raw Data'!O:O,MATCH($B85,'Raw Data'!$C:$C,0)),"-") -> 0.95174108 | H85: =IFERROR(INDEX('Raw Data'!P:P,MATCH($B85,'Raw Data'!$C:$C,0)),"-") -> 0.86501557 | I85: =IFERROR(INDEX('Raw Data'!AD:AD,MATCH($B85,'Raw Data'!$C:$C,0)),"-") -> Operational
A86: =IFERROR(INDEX('Raw Data'!AC:AC,MATCH($B86,'Raw Data'!$C:$C,0)),"") -> Excavator | B86: EX-164 | C86: =IFERROR(INDEX('Raw Data'!D:D,MATCH($B86,'Raw Data'!$C:$C,0)),"-") -> 720.0004 | D86: =IFERROR(INDEX('Raw Data'!E:E,MATCH($B86,'Raw Data'!$C:$C,0)),"-") -> 684.2501 | E86: =IFERROR(INDEX('Raw Data'!H:H,MATCH($B86,'Raw Data'!$C:$C,0)),"-") -> 35.7503 | F86: =IFERROR(INDEX('Raw Data'!J:J,MATCH($B86,'Raw Data'!$C:$C,0)),"-") -> 489.7453 | G86: =IFERROR(INDEX('Raw Data'!O:O,MATCH($B86,'Raw Data'!$C:$C,0)),"-") -> 0.95034683 | H86: =IFERROR(INDEX('Raw Data'!P:P,MATCH($B86,'Raw Data'!$C:$C,0)),"-") -> 0.2737955 | I86: =IFERROR(INDEX('Raw Data'!AD:AD,MATCH($B86,'Raw Data'!$C:$C,0)),"-") -> Operational
A87: =IFERROR(INDEX('Raw Data'!AC:AC,MATCH($B87,'Raw Data'!$C:$C,0)),"") -> Excavator | B87: EX-205 | C87: =IFERROR(INDEX('Raw Data'!D:D,MATCH($B87,'Raw Data'!$C:$C,0)),"-") -> 719.9995 | D87: =IFERROR(INDEX('Raw Data'!E:E,MATCH($B87,'Raw Data'!$C:$C,0)),"-") -> 675.0076 | E87: =IFERROR(INDEX('Raw Data'!H:H,MATCH($B87,'Raw Data'!$C:$C,0)),"-") -> 44.9919 | F87: =IFERROR(INDEX('Raw Data'!J:J,MATCH($B87,'Raw Data'!$C:$C,0)),"-") -> 60.6157 | G87: =IFERROR(INDEX('Raw Data'!O:O,MATCH($B87,'Raw Data'!$C:$C,0)),"-") -> 0.93751121 | H87: =IFERROR(INDEX('Raw Data'!P:P,MATCH($B87,'Raw Data'!$C:$C,0)),"-") -> 0.88532114 | I87: =IFERROR(INDEX('Raw Data'!AD:AD,MATCH($B87,'Raw Data'!$C:$C,0)),"-") -> Operational
A88: =IFERROR(INDEX('Raw Data'!AC:AC,MATCH($B88,'Raw Data'!$C:$C,0)),"") -> Excavator | B88: EX-197 | C88: =IFERROR(INDEX('Raw Data'!D:D,MATCH($B88,'Raw Data'!$C:$C,0)),"-") -> 719.9997 | D88: =IFERROR(INDEX('Raw Data'!E:E,MATCH($B88,'Raw Data'!$C:$C,0)),"-") -> 658.1672 | E88: =IFERROR(INDEX('Raw Data'!H:H,MATCH($B88,'Raw Data'!$C:$C,0)),"-") -> 61.8325 | F88: =IFERROR(INDEX('Raw Data'!J:J,MATCH($B88,'Raw Data'!$C:$C,0)),"-") -> 72.5534 | G88: =IFERROR(INDEX('Raw Data'!O:O,MATCH($B88,'Raw Data'!$C:$C,0)),"-") -> 0.91412149 | H88: =IFERROR(INDEX('Raw Data'!P:P,MATCH($B88,'Raw Data'!$C:$C,0)),"-") -> 0.86506605 | I88: =IFERROR(INDEX('Raw Data'!AD:AD,MATCH($B88,'Raw Data'!$C:$C,0)),"-") -> Operational
A89: =IFERROR(INDEX('Raw Data'!AC:AC,MATCH($B89,'Raw Data'!$C:$C,0)),"") -> Excavator | B89: EX-201 | C89: =IFERROR(INDEX('Raw Data'!D:D,MATCH($B89,'Raw Data'!$C:$C,0)),"-") -> 719.9978 | D89: =IFERROR(INDEX('Raw Data'!E:E,MATCH($B89,'Raw Data'!$C:$C,0)),"-") -> 650.1805 | E89: =IFERROR(INDEX('Raw Data'!H:H,MATCH($B89,'Raw Data'!$C:$C,0)),"-") -> 69.8173 | F89: =IFERROR(INDEX('Raw Data'!J:J,MATCH($B89,'Raw Data'!$C:$C,0)),"-") -> 75.5595 | G89: =IFERROR(INDEX('Raw Data'!O:O,MATCH($B89,'Raw Data'!$C:$C,0)),"-") -> 0.90303123 | H89: =IFERROR(INDEX('Raw Data'!P:P,MATCH($B89,'Raw Data'!$C:$C,0)),"-") -> 0.8606467 | I89: =IFERROR(INDEX('Raw Data'!AD:AD,MATCH($B89,'Raw Data'!$C:$C,0)),"-") -> Operational
A90: =IFERROR(INDEX('Raw Data'!AC:AC,MATCH($B90,'Raw Data'!$C:$C,0)),"") -> Excavator | B90: EX-110 | C90: =IFERROR(INDEX('Raw Data'!D:D,MATCH($B90,'Raw Data'!$C:$C,0)),"-") -> 720.0005 | D90: =IFERROR(INDEX('Raw Data'!E:E,MATCH($B90,'Raw Data'!$C:$C,0)),"-") -> 629.496 | E90: =IFERROR(INDEX('Raw Data'!H:H,MATCH($B90,'Raw Data'!$C:$C,0)),"-") -> 90.5045 | F90: =IFERROR(INDEX('Raw Data'!J:J,MATCH($B90,'Raw Data'!$C:$C,0)),"-") -> 41.6722 | G90: =IFERROR(INDEX('Raw Data'!O:O,MATCH($B90,'Raw Data'!$C:$C,0)),"-") -> 0.87429939 | H90: =IFERROR(INDEX('Raw Data'!P:P,MATCH($B90,'Raw Data'!$C:$C,0)),"-") -> 0.90347516 | I90: =IFERROR(INDEX('Raw Data'!AD:AD,MATCH($B90,'Raw Data'!$C:$C,0)),"-") -> Operational
A91: =IFERROR(INDEX('Raw Data'!AC:AC,MATCH($B91,'Raw Data'!$C:$C,0)),"") -> Excavator | B91: EX-161 | C91: =IFERROR(INDEX('Raw Data'!D:D,MATCH($B91,'Raw Data'!$C:$C,0)),"-") -> 720 | D91: =IFERROR(INDEX('Raw Data'!E:E,MATCH($B91,'Raw Data'!$C:$C,0)),"-") -> 629.0516 | E91: =IFERROR(INDEX('Raw Data'!H:H,MATCH($B91,'Raw Data'!$C:$C,0)),"-") -> 90.9484 | F91: =IFERROR(INDEX('Raw Data'!J:J,MATCH($B91,'Raw Data'!$C:$C,0)),"-") -> 77.6967 | G91: =IFERROR(INDEX('Raw Data'!O:O,MATCH($B91,'Raw Data'!$C:$C,0)),"-") -> 0.87368278 | H91: =IFERROR(INDEX('Raw Data'!P:P,MATCH($B91,'Raw Data'!$C:$C,0)),"-") -> 0.8490286 | I91: =IFERROR(INDEX('Raw Data'!AD:AD,MATCH($B91,'Raw Data'!$C:$C,0)),"-") -> Operational
